Workbook

Sheet Dashboard

Sheet Readmefirst
B5: DANH MỤC BÁO CÁO
B7: STT | C7: Nội dung báo cáo | D7: Link
B8: 1 | C8: Danh sách các site | D8: Site list'
B9: =B8+1 -> 2 | C9: Báo cáo kết quả kinh doanh cộng ngang các site tính từ đầu năm đến tháng hiện tại, so sánh cùng kỳ năm trước | D9: Annual_PL conso' | E9: WIP
B10: =B9+1 -> 3 | C10: Báo cáo kết quả kinh doanh hợp nhất từng tháng năm hiện tại, so sánh với budget và so sánh với năm trước | D10: Monthly_PL conso'
B11: =B10+1 -> 4 | C11: Báo cáo Tình hình tài chính (Tài sản, Nợ, Vốn chủ sở hữu) từng tháng năm hiện tại | D11: Conso BS'
B12: =B11+1 -> 5 | C12: Báo cáo kết quả kinh doanh site Hải Dương | D12: HaiDuong
B13: =B12+1 -> 6 | C13: Báo cáo kết quả kinh doanh site Cà Mau | D13: CaMau
B14: =B13+1 -> 7 | C14: Báo cáo kết quả kinh doanh site Thanh Hóa | D14: ThanhHoa
B15: =B14+1 -> 8 | C15: Báo cáo kết quả kinh doanh site Thaí Nguyên | D15: ThaiNguyen
B16: =B15+1 -> 9 | C16: Báo cáo kết quả kinh doanh site Thaí Bình | D16: ThaiBinh
B17: =B16+1 -> 10 | C17: Báo cáo kết quả kinh doanh site Yết Kiêu | D17: YetKieu
B18: =B17+1 -> 11 | C18: Báo cáo kết quả kinh doanh site Nha Trang | D18: NhaTrang
B19: =B18+1 -> 12 | C19: Báo cáo kết quả kinh doanh site Thạch Thất | D19: ThachThat
B20: =B19+1 -> 13 | C20: Báo cáo kết quả kinh doanh site Sóc Sơn | D20: SocSon-1'
B21: =B20+1 -> 14 | C21: Báo cáo kết quả kinh doanh các site liên kết | D21: Site liên kết'
B22: =B21+1 -> 15 | C22: Báo cáo kết quả kinh doanh HM Saigon | D22: HM-2'
B23: =B22+1 -> 16 | C23: Báo cáo kết quả kinh doanh site Hà Tĩnh
B24: =B23+1 -> 17 | C24: Báo cáo kết quả kinh doanh HO | D24: HO
B25: =B24+1 -> 18 | C25: Điểm hòa vốn từng site | D25: Điểm hòa vốn'
B26: =B25+1 -> 19 | C26: Dự báo dòng tiền năm 2026 | D26: CF forecast'
B27: =B26+1 -> 20 | C27: Dự báo kết quả kinh doanh toàn hệ thống
B28: =B27+1 -> 21 | C28: Dự báo kết quả kinh doanh site Hải Dương
B29: =B28+1 -> 22 | C29: Dự báo kết quả kinh doanh site Cà Mau
B30: =B29+1 -> 23 | C30: Dự báo kết quả kinh doanh site Thanh Hóa
B31: =B30+1 -> 24 | C31: Dự báo kết quả kinh doanh site Thaí Nguyên | D31: ThaiNguyen2
B32: =B31+1 -> 25 | C32: Dự báo kết quả kinh doanh site Thaí Bình | D32: ThaiBinh2
B33: =B32+1 -> 26 | C33: Dự báo kết quả kinh doanh site Yết Kiêu | D33: YetKieu-2'
B34: =B33+1 -> 27 | C34: Dự báo kết quả kinh doanh site Nha Trang | D34: NhaTrang-2'
B35: =B34+1 -> 28 | C35: Dự báo kết quả kinh doanh site Thạch Thất | D35: ThachThat
B36: =B35+1 -> 29 | C36: Dự báo kết quả kinh doanh site Sóc Sơn | D36: SocSon
B37: =B36+1 -> 30 | C37: Dự báo kết quả kinh doanh các site liên kết | D37: Site liên kết'
B38: =B37+1 -> 31 | C38: Dự báo kết quả kinh doanh HM Saigon | D38: HM-3'
B39: =B38+1 -> 32 | C39: Dự báo kết quả kinh doanh site Hà Tĩnh | D39: Hà Tĩnh'
B40: =B39+1 -> 33 | C40: Dự báo kết quả kinh doanh HO | D40: HO-2'
B41: =B40+1 -> 34 | C41: Dự báo chị phí bảo trì sửa chữa thay thế máy móc | D41: Maintenance
B42: =B41+1 -> 35 | C42: Bảng tính lãi vay site Cà Mau | D42: VTB_CaMau
... B47: =B46+1 -> 40 | C47: Bảng tính lãi vay site Nha Trang | D47: VTB_Nha trang.'

Sheet Annual_PL conso
B6: BÁO CÁO KẾT QUẢ HOẠT ĐỘNG KINH DOANH HỢP NHẤT
B8: Năm tài chính 2025 | Q8: --------Tổng--------- | S8: ------vs last year-------
B9: VND triệu | F9: Hải Dương | G9: Cà Mau | H9: Thanh Hóa | I9: T.Nguyên | J9: Thái Bình | K9: Yết Kiêu | L9: Nha Trang | M9: T.Thất | N9: Sóc Sơn | O9: HO | P9: Site LK | Q9: VND triệu | R9: %DT | S9: VND triệu | T9: % | W9: Năm 2025 | X9: Trung Bình/tháng
B11: Doanh thu | V11: Hải Dương | W11: 11146.22 | X11: =W11/12 -> 928.85167
C12: Chẩn đoán hình ảnh | V12: Cà Mau | W12: 5416.52 | X12: =W12/12 -> 451.37667
D13: MRI | F13: =HaiDuong!R42 -> 8990.3 | G13: =CaMau!R12 -> 5194.42 | H13: =ThanhHoa!R12 -> 3505.3648 | I13: =ThaiNguyen!R12 -> 3278.95 | J13: =ThaiBinh!R12 -> 1940.29 | K13: =YetKieu!R12 -> 5743.65 | L13: =NhaTrang!R12 -> 5106.311 | M13: 0 | N13: ='SocSon-1'!R22 -> 210.99 | Q13: =SUM(F13:P13) -> 33970.276 | R13: =IFERROR(Q13/Q$20,"") -> 0.74773973 | V13: Thanh Hóa | W13: 10912.091 | X13: =W13/12 -> 909.34087
D14: CT | F14: =HaiDuong!R44 -> 1643.3 | G14: =CaMau!R14 -> 0 | H14: =ThanhHoa!R14 -> 7406.7257 | I14: =ThaiNguyen!R14 -> 35 | J14: =ThaiBinh!R14 -> 0 | K14: =YetKieu!R14 -> 277.346 | L14: =NhaTrang!R13 -> 353.465 | M14: =ThachThat!R12 -> 693.3 | N14: 0 | Q14: =SUM(F14:P14) -> 10409.137 | R14: =IFERROR(Q14/Q$20,"") -> 0.22912163 | V14: T.Nguyên | W14: 3322.05 | X14: =W14/12 -> 276.8375
D15: Mammo X-Quang | F15: =HaiDuong!R43 -> 124.3 | G15: =CaMau!R13 -> 222.1 | H15: =ThanhHoa!R13 -> 0 | I15: =ThaiNguyen!R13 -> 0 | J15: =ThaiBinh!R13 -> 0 | K15: =YetKieu!R13 -> 79.0656 | L15: =NhaTrang!R14 -> 70.12 | M15: =0 -> 0 | N15: =0 -> 0 | Q15: =SUM(F15:P15) -> 495.5856 | R15: =IFERROR(Q15/Q$20,"") -> 0.010908626 | V15: Thái Bình | W15: 1946.44 | X15: =W15/12 -> 162.20333
D16: X-Quang | F16: =HaiDuong!R45 -> 278.5 | G16: =CaMau!R15 -> 0 | H16: =ThanhHoa!R15 -> 0 | I16: =ThaiNguyen!R15 -> 8.1 | J16: =ThaiBinh!R15 -> 6.15 | K16: =YetKieu!R15 -> 67.657 | L16: =0 -> 0 | M16: 0 | N16: 0 | Q16: =SUM(F16:P16) -> 360.407 | R16: =IFERROR(Q16/Q$20,"") -> 0.0079331305 | V16: Yết Kiêu | W16: 6197.5786 | X16: =W16/12 -> 516.46488
D17: Siêu âm | F17: =HaiDuong!R46 -> 114.9 | G17: =CaMau!R16 -> 0 | H17: =ThanhHoa!R16 -> 0 | I17: =ThaiNguyen!R16 -> 0 | J17: =ThaiBinh!R16 -> 0 | K17: =YetKieu!R16 -> 16.64 | L17: 0 | M17: 0 | N17: 0 | Q17: =SUM(F17:P17) -> 131.54 | R17: =IFERROR(Q17/Q$20,"") -> 0.0028954043 | V17: Nha Trang | W17: 5532.746 | X17: =W17/12 -> 461.06217
C18: Tổng- Chẩn đoán hình ảnh | F18: =SUBTOTAL(9,F13:F17) -> 11151.3 | G18: =SUBTOTAL(9,G13:G17) -> 5416.52 | H18: =SUBTOTAL(9,H13:H17) -> 10912.091 | I18: =SUBTOTAL(9,I13:I17) -> 3322.05 | J18: =SUBTOTAL(9,J13:J17) -> 1946.44 | K18: =SUBTOTAL(9,K13:K17) -> 6184.3586 | L18: =SUBTOTAL(9,L13:L17) -> 5529.896 | M18: =SUBTOTAL(9,M13:M17) -> 693.3 | N18: =SUBTOTAL(9,N13:N17) -> 210.99 | Q18: =SUM(F18:N18) -> 45366.945 | R18: =IFERROR(Q18/Q$20,"") -> 0.99859852 | V18: T.Thất | W18: 693.3 | X18: =W18/12 -> 57.775
C19: Tổng- Khác | F19: =HaiDuong!R48 -> 18.92 | G19: =CaMau!R18 -> 0 | H19: =ThanhHoa!R18 -> 0 | I19: =ThaiNguyen!R18 -> 0 | J19: =0 -> 0 | K19: =YetKieu!R17 -> 41.9 | L19: =NhaTrang!R15 -> 2.85 | M19: =0 -> 0 | N19: =0 -> 0 | Q19: =SUM(F19:N19) -> 63.67 | R19: =IFERROR(Q19/Q$20,"") -> 0.0014014778 | V19: Sóc Sơn | W19: 210.99 | X19: =W19/12 -> 17.5825
B20: Tổng- Doanh thu | F20: =SUM(F18:F19) -> 11170.22 | G20: =SUM(G18:G19) -> 5416.52 | H20: =SUM(H18:H19) -> 10912.091 | I20: =SUM(I18:I19) -> 3322.05 | J20: =SUM(J18:J19) -> 1946.44 | K20: =SUM(K18:K19) -> 6226.2586 | L20: =SUM(L18:L19) -> 5532.746 | M20: =SUM(M18:M19) -> 693.3 | N20: =SUM(N18:N19) -> 210.99 | Q20: =SUM(F20:N20) -> 45430.615 | R20: =IFERROR(Q20/Q$20,"") -> 1 | W20: =SUM(W11:W19) -> 45377.935 | X20: =SUM(X11:X19) -> 3781.4946
B21: Giảm trừ doanh thu | F21: =HaiDuong!R50 -> 72.435 | G21: =CaMau!R20 -> 0.9 | H21: =ThanhHoa!R20 -> 8.32 | I21: =ThaiNguyen!R20 -> 675.48 | J21: =ThaiBinh!R18 -> 0 | K21: =YetKieu!R19 -> 0 | L21: =NhaTrang!R21 -> 0 | M21: =ThachThat!R14 -> 0 | N21: ='SocSon-1'!R23 -> 0 | Q21: =SUM(F21:P21) -> 757.135 | R21: =IFERROR(Q21/Q$20,"") -> 0.016665744
B22: Biến phí | R22: =IFERROR(Q22/Q$20,"") -> 0
C23: Vật tư tiêu hao | F23: =HaiDuong!R57 -> 479.98592 | G23: =CaMau!R27 -> 25.7917 | H23: =ThanhHoa!R26 -> 316.33424 | I23: =ThaiNguyen!R27 -> 111.4161 | J23: =ThaiBinh!R21 -> 109.8095 | K23: =YetKieu!R28 -> 608.01031 | L23: =NhaTrang!R24 -> 206.72404 | M23: =ThachThat!R17 -> 34.056 | N23: ='SocSon-1'!R26 -> 11.4673 | Q23: =SUM(F23:P23) -> 1903.5951 | R23: =IFERROR(Q23/Q$20,"") -> 0.041901152
C24: Chi phí đọc kết quả online | F24: =HaiDuong!R58 -> 742.834 | G24: =CaMau!R28 -> 350.505 | H24: =ThanhHoa!R27 -> 929.12 | I24: =ThaiNguyen!R28 -> 207.191 | J24: =ThaiBinh!R22 -> 198.598 | K24: =YetKieu!R29 -> 378.943 | L24: =NhaTrang!R27 -> 373.505 | M24: =ThachThat!R20 -> 94.53 | N24: ='SocSon-1'!R27 -> 20.01 | Q24: =SUM(F24:P24) -> 3295.236 | R24: =IFERROR(Q24/Q$20,"") -> 0.072533378
C25: Tiền thuốc | F25: =HaiDuong!R59 -> 322.55584 | G25: =CaMau!R29 -> 0 | H25: =ThanhHoa!R28 -> 623.05 | I25: =ThaiNguyen!R29 -> 33.748 | J25: =ThaiBinh!R23 -> 2.808616 | K25: =YetKieu!R30 -> 0 | L25: 0 | M25: 0 | N25: ='SocSon-1'!R28 -> 0 | Q25: =SUM(F25:P25) -> 982.16246 | R25: =IFERROR(Q25/Q$20,"") -> 0.021618956
C26: Tư vấn chuyên môn | F26: =HaiDuong!R60 -> 1339.1 | G26: =CaMau!R30 -> 787.15 | H26: =ThanhHoa!R29 -> 1112.695 | I26: =ThaiNguyen!R30 -> 466.4 | J26: =ThaiBinh!R24 -> 306.5 | K26: =YetKieu!R31 -> 898.654 | L26: =NhaTrang!R26 -> 911.875 | M26: =ThachThat!R19 -> 103 | N26: ='SocSon-1'!R29 -> 18.23 | Q26: =SUM(F26:P26) -> 5943.604 | R26: =IFERROR(Q26/Q$20,"") -> 0.13082816
C27: Thưởng hiệu quả kinh doanh | F27: =HaiDuong!R61 -> 278.42 | G27: =CaMau!R31 -> 0 | H27: =ThanhHoa!R30 -> 331.4264 | I27: =ThaiNguyen!R31 -> 73.93 | J27: =ThaiBinh!R25 -> 12.04 | K27: =YetKieu!R32 -> 179.88638 | L27: =NhaTrang!R25 -> 90.2997 | M27: =ThachThat!R18 -> 0 | N27: ='SocSon-1'!R30 -> 0 | Q27: =SUM(F27:P27) -> 966.00248 | R27: =IFERROR(Q27/Q$20,"") -> 0.021263249
C28: Truyền thông marketing | F28: =HaiDuong!R62 -> 78.673914 | G28: =CaMau!R32 -> 0 | H28: =ThanhHoa!R31 -> 92.671215 | I28: =ThaiNguyen!R32 -> 97.429016 | J28: =ThaiBinh!R26 -> 63.716182 | K28: =YetKieu!R33 -> 0 | L28: 0 | M28: 0 | N28: ='SocSon-1'!R31 -> 0 | Q28: =SUM(F28:P28) -> 332.49033 | R28: =IFERROR(Q28/Q$20,"") -> 0.0073186402
C29: Tổng- Biến phí | F29: =SUBTOTAL(9,F23:F28) -> 3241.5697 | G29: =SUBTOTAL(9,G23:G28) -> 1163.4467 | H29: =SUBTOTAL(9,H23:H28) -> 3405.2969 | I29: =SUBTOTAL(9,I23:I28) -> 990.11412 | J29: =SUBTOTAL(9,J23:J28) -> 693.4723 | K29: =SUBTOTAL(9,K23:K28) -> 2065.4937 | L29: =SUBTOTAL(9,L23:L28) -> 1582.4037 | M29: =SUBTOTAL(9,M23:M28) -> 231.586 | N29: =SUBTOTAL(9,N23:N28) -> 49.7073 | Q29: =SUM(Q23:Q28) -> 13423.09 | R29: =IFERROR(Q29/Q$20,"") -> 0.29546354
B30: Lãi trên biến phí | F30: =F20-F29-F21 -> 7856.2153 | G30: =G20-G29-G21 -> 4252.1733 | H30: =H20-H29-H21 -> 7498.4736 | I30: =I20-I29-I21 -> 1656.4559 | J30: =J20-J29-J21 -> 1252.9677 | K30: =K20-K29-K21 -> 4160.7649 | L30: =L20-L29-L21 -> 3950.3423 | M30: =M20-M29-M21 -> 461.714 | N30: =N20-N29-N21 -> 161.2827 | Q30: =Q20-Q29-Q21 -> 31250.39 | R30: =IFERROR(Q30/Q$20,"") -> 0.68787072
B31: Định phí | R31: =IFERROR(Q31/Q$20,"") -> 0
C32: Chi phí nhân sự | F32: =HaiDuong!R66-HO!R13 -> 1977.5054 | G32: =CaMau!R36 -> 762.02839 | H32: =ThanhHoa!R35 -> 1752.3483 | I32: =ThaiNguyen!R36 -> 1182.95 | J32: =ThaiBinh!R28 -> 829.78285 | K32: =YetKieu!R35 -> 1248.3208 | L32: =NhaTrang!R30 -> 973.1919 | M32: =ThachThat!R23 -> 176.54 | N32: ='SocSon-1'!R33 -> 106.049 | Q32: =SUM(F32:P32) -> 9008.7166 | R32: =IFERROR(Q32/Q$20,"") -> 0.19829616
C33: Chi phí thuê địa điểm | F33: =HaiDuong!R67 -> 362.6895 | G33: =CaMau!R37 -> 240 | H33: =ThanhHoa!R36 -> 738.41666 | I33: =ThaiNguyen!R37 -> 621.21911 | J33: =ThaiBinh!R29 -> 264 | K33: =SUM(YetKieu!R36:R38) -> 3102.6144 | L33: =SUM(NhaTrang!R31:R32) -> 1985.9138 | M33: =SUM(ThachThat!R24:R26) -> 74.638962 | N33: ='SocSon-1'!R34 -> 22 | Q33: =SUM(F33:P33) -> 7411.4925 | R33: =IFERROR(Q33/Q$20,"") -> 0.16313872
C34: Chi phí bảo dưỡng sửa chữa | F34: =HaiDuong!R68 -> 0 | G34: =CaMau!R38 -> 0 | H34: =ThanhHoa!R37 -> 0 | I34: =ThaiNguyen!R38 -> 0 | J34: =ThaiBinh!R30 -> 0 | K34: 0 | L34: 0 | M34: 0 | N34: ='SocSon-1'!R35 -> 0 | Q34: =SUM(F34:P34) -> 0
C35: Chi phí vận hành thường xuyên | F35: =HaiDuong!R69 -> 1079.6883 | G35: =CaMau!R39 -> 470.75663 | H35: =ThanhHoa!R38 -> 684.86413 | I35: =ThaiNguyen!R39 -> 772.58742 | J35: =ThaiBinh!R31 -> 539.18652 | K35: 0 | L35: 0 | M35: 0 | N35: ='SocSon-1'!R36 -> 20.219222 | Q35: =SUM(F35:P35) -> 3567.3022 | R35: =IFERROR(Q35/Q$20,"") -> 0.078521988
C36: Chi phí khác | F36: =HaiDuong!R70 -> 29.193604 | G36: =CaMau!R40 -> 184.40128 | H36: =ThanhHoa!R39 -> 318.65076 | I36: =ThaiNguyen!R40 -> 94.643845 | J36: =ThaiBinh!R32 -> 22.070896 | K36: =YetKieu!R39 -> 118.38815 | L36: =NhaTrang!R33 -> 60.796074 | M36: 0 | N36: ='SocSon-1'!R37 -> 76.23 | Q36: =SUM(F36:P36) -> 904.3746 | R36: =IFERROR(Q36/Q$20,"") -> 0.019906721
C37: Tổng- Định phí | F37: =SUBTOTAL(9,F32:F36) -> 3449.0767 | G37: =SUBTOTAL(9,G32:G36) -> 1657.1863 | H37: =SUBTOTAL(9,H32:H36) -> 3494.2799 | I37: =SUBTOTAL(9,I32:I36) -> 2671.4004 | J37: =SUBTOTAL(9,J32:J36) -> 1655.0403 | K37: =SUBTOTAL(9,K32:K36) -> 4469.3234 | L37: =SUBTOTAL(9,L32:L36) -> 3019.9018 | M37: =SUBTOTAL(9,M32:M36) -> 251.17896 | N37: =SUBTOTAL(9,N32:N36) -> 224.49822 | Q37: =SUBTOTAL(9,Q32:Q36) -> 20891.886 | R37: =IFERROR(Q37/Q$20,"") -> 0.45986359
B38: EBITDA tại chi nhánh | F38: =F30-F37 -> 4407.1386 | G38: =G30-G37 -> 2594.987 | H38: =H30-H37 -> 4004.1938 | I38: =I30-I37 -> -1014.9445 | J38: =J30-J37 -> -402.07256 | K38: =K30-K37 -> -308.55851 | L38: =L30-L37 -> 930.4405 | M38: =M30-M37 -> 210.53504 | N38: =N30-N37 -> -63.215522 | Q38: =Q30-Q37 -> 10358.504 | R38: =IFERROR(Q38/Q$20,"") -> 0.22800712
B39: Lợi nhuận từ site liên kết | P39: ='Site liên kết'!R20 -> 3442.2475 | Q39: =SUM(F39:P39) -> 3442.2475 | R39: =IFERROR(Q39/Q$20,"") -> 0.075769334
B40: Chi phí tại HO
C41: Chi phí nhân sự | O41: =SUM(HO!R18,HO!R26) -> 2889.3228 | Q41: =SUM(F41:P41) -> 2889.3228 | R41: =IFERROR(Q41/Q$20,"") -> 0.063598585
C42: Chi phí thuê văn mặt bằng, điện nước, viễn thông | O42: =SUM(HO!R19:R20,HO!R28) -> 741.07605 | Q42: =SUM(F42:P42) -> 741.07605 | R42: =IFERROR(Q42/Q$20,"") -> 0.016312261
C43: Chi phí văn phòng phẩm dụng cụ | O43: =SUM(HO!R21,HO!R29) -> 85.300047 | Q43: =SUM(F43:P43) -> 85.300047 | R43: =IFERROR(Q43/Q$20,"") -> 0.0018775895
C44: Chi phí đối ngoại tiếp khách | O44: =SUM(HO!R23,HO!R27) -> 103.96385 | Q44: =SUM(F44:P44) -> 103.96385 | R44: =IFERROR(Q44/Q$20,"") -> 0.0022884095
C45: Chi phí dịch vụ chuyên nghiệp | O45: =SUM(HO!R22) -> 122.21769 | Q45: =SUM(F45:P45) -> 122.21769 | R45: =IFERROR(Q45/Q$20,"") -> 0.0026902054
C46: Chi phí khác | O46: =SUM(HO!R24,HO!R30) -> 549.49356 | Q46: =SUM(F46:P46) -> 549.49356 | R46: =IFERROR(Q46/Q$20,"") -> 0.012095226
C47: Tổng - Chi phí HO | F47: =SUM(F41:F46) -> 0 | G47: =SUM(G41:G46) -> 0 | H47: =SUM(H41:H46) -> 0 | I47: =SUM(I41:I46) -> 0 | J47: =SUM(J41:J46) -> 0 | K47: =SUM(K41:K46) -> 0 | L47: =SUM(L41:L46) -> 0 | M47: =SUM(M41:M46) -> 0 | ... Q47: =SUM(Q41:Q46) -> 4491.374 | R47: =IFERROR(Q47/Q$20,"") -> 0.098862277
...

Sheet Monthly_PL conso
B6: BÁO CÁO KẾT QUẢ HOẠT ĐỘNG KINH DOANH HỢP NHẤT
F7: A | G7: A | H7: A | I7: A | J7: A | K7: A | L7: A | M7: A | N7: A | O7: A | P7: A | Q7: A
B8: Năm tài chính 2025 | F8: Tháng | R8: -------------------------Tổng-------------------------- | U8: ------%Doanh thu------- | X8: -----------vs-------------
B9: VND triệu | F9: 1 | G9: 2 | H9: 3 | I9: 4 | J9: 5 | K9: 6 | L9: 7 | M9: 8 | N9: 9 | O9: 10 | P9: 11 | Q9: 12 | R9: Year to date | S9: Year to go | T9: LATEST EST | U9: YTD | V9: YTG | W9: LE | X9: Last month | Y9: Last year
B11: Doanh thu
C12: Chẩn đoán hình ảnh
D13: MRI | F13: =SUBTOTAL(9,F14:F22) -> 1252.37 | G13: =SUBTOTAL(9,G14:G22) -> 2129.88 | H13: =SUBTOTAL(9,H14:H22) -> 2521.672 | I13: =SUBTOTAL(9,I14:I22) -> 2779.2616 | J13: =SUBTOTAL(9,J14:J22) -> 2952.0801 | K13: =SUBTOTAL(9,K14:K22) -> 3027.2768 | L13: =SUBTOTAL(9,L14:L22) -> 3317.85 | M13: =SUBTOTAL(9,M14:M22) -> 3450.45 | ... Q13: =SUBTOTAL(9,Q14:Q22) -> 3173.676 | R13: =SUMIFS($F13:$Q13,$F$7:$Q$7,"A") -> 33970.276 | S13: =SUMIFS($F13:$Q13,$F$7:$Q$7,"B") -> 0 | T13: =SUM(R13:S13) -> 33970.276 | U13: =IFERROR(R13/R$45,"") -> 0.74773973 | V13: =IFERROR(S13/S$45,"") | W13: =IFERROR(T13/T$45,"") -> 0.74773973
E14: Hải Dương | F14: =HaiDuong!F42 -> 480.4 | G14: =HaiDuong!G42 -> 766.6 | H14: =HaiDuong!H42 -> 864 | I14: =HaiDuong!I42 -> 1002.4 | J14: =HaiDuong!J42 -> 860.4 | K14: =HaiDuong!K42 -> 801.6 | L14: =HaiDuong!L42 -> 845.2 | M14: =HaiDuong!M42 -> 676.4 | ... Q14: =HaiDuong!Q42 -> 700.4 | R14: =SUMIFS($F14:$Q14,$F$7:$Q$7,"A") -> 8990.3 | S14: =SUMIFS($F14:$Q14,$F$7:$Q$7,"B") -> 0 | T14: =SUM(R14:S14) -> 8990.3 | U14: =IFERROR(R14/R$45,"") -> 0.19789078 | V14: =IFERROR(S14/S$45,"") | W14: =IFERROR(T14/T$45,"") -> 0.19789078
E15: Cà Mau | F15: =CaMau!F12 -> 185.58 | G15: =CaMau!G12 -> 339.3 | H15: =CaMau!H12 -> 407.7 | I15: =CaMau!I12 -> 500.4 | J15: =CaMau!J12 -> 477 | K15: =CaMau!K12 -> 592.83 | L15: =CaMau!L12 -> 457.65 | M15: =CaMau!M12 -> 463.5 | ... Q15: =CaMau!Q12 -> 353.65 | R15: =SUMIFS($F15:$Q15,$F$7:$Q$7,"A") -> 5194.42 | S15: =SUMIFS($F15:$Q15,$F$7:$Q$7,"B") -> 0 | T15: =SUM(R15:S15) -> 5194.42 | U15: =IFERROR(R15/R$45,"") -> 0.11433743 | V15: =IFERROR(S15/S$45,"") | W15: =IFERROR(T15/T$45,"") -> 0.11433743
E16: Thanh Hóa | F16: =ThanhHoa!F12 -> 177.8 | G16: =ThanhHoa!G12 -> 333.2 | H16: =ThanhHoa!H12 -> 304.672 | I16: =ThanhHoa!I12 -> 403.2716 | J16: =ThanhHoa!J12 -> 537.3301 | K16: =ThanhHoa!K12 -> 256.1668 | L16: =ThanhHoa!L12 -> 296.2 | M16: =ThanhHoa!M12 -> 376.5 | ... Q16: =ThanhHoa!Q12 -> 155.5 | R16: =SUMIFS($F16:$Q16,$F$7:$Q$7,"A") -> 3505.3648 | S16: =SUMIFS($F16:$Q16,$F$7:$Q$7,"B") -> 0 | T16: =SUM(R16:S16) -> 3505.3648 | U16: =IFERROR(R16/R$45,"") -> 0.077158647 | V16: =IFERROR(S16/S$45,"") | W16: =IFERROR(T16/T$45,"") -> 0.077158647
E17: Thái Nguyên | F17: =ThaiNguyen!F12 -> 75.6 | G17: =ThaiNguyen!G12 -> 127.9 | H17: =ThaiNguyen!H12 -> 206.55 | I17: =ThaiNguyen!I12 -> 173.9 | J17: =ThaiNguyen!J12 -> 239.2 | K17: =ThaiNguyen!K12 -> 249.2 | L17: =ThaiNguyen!L12 -> 272.4 | M17: =ThaiNguyen!M12 -> 344.6 | ... Q17: =ThaiNguyen!Q12 -> 448.3 | R17: =SUMIFS($F17:$Q17,$F$7:$Q$7,"A") -> 3278.95 | S17: =SUMIFS($F17:$Q17,$F$7:$Q$7,"B") -> 0 | T17: =SUM(R17:S17) -> 3278.95 | U17: =IFERROR(R17/R$45,"") -> 0.072174898 | V17: =IFERROR(S17/S$45,"") | W17: =IFERROR(T17/T$45,"") -> 0.072174898
E18: Thái Bình | F18: =ThaiBinh!F12 -> 0 | G18: =ThaiBinh!G12 -> 0 | H18: =ThaiBinh!H12 -> 0 | I18: =ThaiBinh!I12 -> 0 | J18: =ThaiBinh!J12 -> 0 | K18: =ThaiBinh!K12 -> 81.35 | L18: =ThaiBinh!L12 -> 311.85 | M18: =ThaiBinh!M12 -> 503.9 | ... Q18: =ThaiBinh!Q12 -> 225.57 | R18: =SUMIFS($F18:$Q18,$F$7:$Q$7,"A") -> 1940.29 | S18: =SUMIFS($F18:$Q18,$F$7:$Q$7,"B") -> 0 | T18: =SUM(R18:S18) -> 1940.29 | U18: =IFERROR(R18/R$45,"") -> 0.042708865 | V18: =IFERROR(S18/S$45,"") | W18: =IFERROR(T18/T$45,"") -> 0.042708865
E19: Yết Kiêu | F19: =YetKieu!F12 -> 156.35 | G19: =YetKieu!G12 -> 265.34 | H19: =YetKieu!H12 -> 331.05 | I19: =YetKieu!I12 -> 299.79 | J19: =YetKieu!J12 -> 461 | K19: =YetKieu!K12 -> 563.95 | L19: =YetKieu!L12 -> 637.81 | M19: =YetKieu!M12 -> 589.05 | ... Q19: =YetKieu!Q12 -> 647.876 | R19: =SUMIFS($F19:$Q19,$F$7:$Q$7,"A") -> 5743.65 | S19: =SUMIFS($F19:$Q19,$F$7:$Q$7,"B") -> 0 | T19: =SUM(R19:S19) -> 5743.65 | U19: =IFERROR(R19/R$45,"") -> 0.12642686 | V19: =IFERROR(S19/S$45,"") | W19: =IFERROR(T19/T$45,"") -> 0.12642686
E20: Nha Trang | F20: =NhaTrang!F12 -> 176.64 | G20: =NhaTrang!G12 -> 297.54 | H20: =NhaTrang!H12 -> 407.7 | I20: =NhaTrang!I12 -> 399.5 | J20: =NhaTrang!J12 -> 377.15 | K20: =NhaTrang!K12 -> 482.18 | L20: =NhaTrang!L12 -> 496.74 | M20: =NhaTrang!M12 -> 496.5 | ... Q20: =NhaTrang!Q12 -> 530.14 | R20: =SUMIFS($F20:$Q20,$F$7:$Q$7,"A") -> 5106.311 | S20: =SUMIFS($F20:$Q20,$F$7:$Q$7,"B") -> 0 | T20: =SUM(R20:S20) -> 5106.311 | U20: =IFERROR(R20/R$45,"") -> 0.11239802 | V20: =IFERROR(S20/S$45,"") | W20: =IFERROR(T20/T$45,"") -> 0.11239802
E21: Thạch Thất | F21: =0 -> 0 | G21: =0 -> 0 | H21: =0 -> 0 | I21: =0 -> 0 | J21: =0 -> 0 | K21: =0 -> 0 | L21: =0 -> 0 | M21: =0 -> 0 | ... Q21: =0 -> 0 | R21: =SUMIFS($F21:$Q21,$F$7:$Q$7,"A") -> 0 | S21: =SUMIFS($F21:$Q21,$F$7:$Q$7,"B") -> 0 | T21: =SUM(R21:S21) -> 0 | U21: =IFERROR(R21/R$45,"") -> 0 | V21: =IFERROR(S21/S$45,"") | W21: =IFERROR(T21/T$45,"") -> 0
E22: Sóc Sơn | F22: ='SocSon-1'!F22 -> 0 | G22: ='SocSon-1'!G22 -> 0 | H22: ='SocSon-1'!H22 -> 0 | I22: ='SocSon-1'!I22 -> 0 | J22: ='SocSon-1'!J22 -> 0 | K22: ='SocSon-1'!K22 -> 0 | L22: ='SocSon-1'!L22 -> 0 | M22: ='SocSon-1'!M22 -> 0 | ... Q22: ='SocSon-1'!Q22 -> 112.24 | R22: =SUMIFS($F22:$Q22,$F$7:$Q$7,"A") -> 210.99 | S22: =SUMIFS($F22:$Q22,$F$7:$Q$7,"B") -> 0 | T22: =SUM(R22:S22) -> 210.99 | U22: =IFERROR(R22/R$45,"") -> 0.004644225 | V22: =IFERROR(S22/S$45,"") | W22: =IFERROR(T22/T$45,"") -> 0.004644225
D23: CT | F23: =SUBTOTAL(9,F24:F29) -> 198.65 | G23: =SUBTOTAL(9,G24:G29) -> 892.385 | H23: =SUBTOTAL(9,H24:H29) -> 1292.59 | I23: =SUBTOTAL(9,I24:I29) -> 1093.3588 | J23: =SUBTOTAL(9,J24:J29) -> 1199.2536 | K23: =SUBTOTAL(9,K24:K29) -> 1422.221 | L23: =SUBTOTAL(9,L24:L29) -> 996.996 | M23: =SUBTOTAL(9,M24:M29) -> 470.641 | ... T23: =SUBTOTAL(9,T24:T29) -> 10409.137 | U23: =IFERROR(R23/R$45,"") -> 0.22912163 | V23: =IFERROR(S23/S$45,"") | W23: =IFERROR(T23/T$45,"") -> 0.22912163
E24: Hải Dương | F24: =HaiDuong!F44 -> 125.8 | G24: =HaiDuong!G44 -> 171 | H24: =HaiDuong!H44 -> 199.5 | I24: =HaiDuong!I44 -> 239.5 | J24: =HaiDuong!J44 -> 155.5 | K24: =HaiDuong!K44 -> 118.5 | L24: =HaiDuong!L44 -> 94.5 | M24: =HaiDuong!M44 -> 93 | ... Q24: =HaiDuong!Q44 -> 134.9 | R24: =SUMIFS($F24:$Q24,$F$7:$Q$7,"A") -> 1643.3 | S24: =SUMIFS($F24:$Q24,$F$7:$Q$7,"B") -> 0 | T24: =SUM(R24:S24) -> 1643.3 | U24: =IFERROR(R24/R$45,"") -> 0.036171643 | V24: =IFERROR(S24/S$45,"") | W24: =IFERROR(T24/T$45,"") -> 0.036171643
E25: Thanh Hóa | F25: =ThanhHoa!F14 -> 54.6 | G25: =ThanhHoa!G14 -> 690 | H25: =ThanhHoa!H14 -> 1059.2 | I25: =ThanhHoa!I14 -> 810.2388 | J25: =ThanhHoa!J14 -> 1010.7436 | K25: =ThanhHoa!K14 -> 1263.131 | L25: =ThanhHoa!L14 -> 862.961 | M25: =ThanhHoa!M14 -> 342.006 | ... Q25: =ThanhHoa!Q14 -> 38.4 | R25: =SUMIFS($F25:$Q25,$F$7:$Q$7,"A") -> 7406.7257 | S25: =SUMIFS($F25:$Q25,$F$7:$Q$7,"B") -> 0 | T25: =SUM(R25:S25) -> 7406.7257 | U25: =IFERROR(R25/R$45,"") -> 0.1630338 | V25: =IFERROR(S25/S$45,"") | W25: =IFERROR(T25/T$45,"") -> 0.1630338
E26: Thái Nguyên | F26: =ThaiNguyen!F14 -> 0 | G26: =ThaiNguyen!G14 -> 0 | H26: =ThaiNguyen!H14 -> 0 | I26: =ThaiNguyen!I14 -> 0 | J26: =ThaiNguyen!J14 -> 0 | K26: =ThaiNguyen!K14 -> 0 | L26: =ThaiNguyen!L14 -> 1.5 | M26: =ThaiNguyen!M14 -> 1 | ... Q26: =ThaiNguyen!Q14 -> 15 | R26: =SUMIFS($F26:$Q26,$F$7:$Q$7,"A") -> 35 | S26: =SUMIFS($F26:$Q26,$F$7:$Q$7,"B") -> 0 | T26: =SUM(R26:S26) -> 35 | U26: =IFERROR(R26/R$45,"") -> 0.00077040559 | V26: =IFERROR(S26/S$45,"") | W26: =IFERROR(T26/T$45,"") -> 0.00077040559
E27: Yết Kiêu | F27: =YetKieu!F14 -> 10.95 | G27: =YetKieu!G14 -> 16.85 | H27: =YetKieu!H14 -> 16.34 | I27: =YetKieu!I14 -> 16.22 | J27: =YetKieu!J14 -> 19.56 | K27: =YetKieu!K14 -> 26.14 | L27: =YetKieu!L14 -> 23.61 | M27: =YetKieu!M14 -> 19.11 | ... Q27: =YetKieu!Q14 -> 47.3 | R27: =SUMIFS($F27:$Q27,$F$7:$Q$7,"A") -> 277.346 | S27: =SUMIFS($F27:$Q27,$F$7:$Q$7,"B") -> 0 | T27: =SUM(R27:S27) -> 277.346 | U27: =IFERROR(R27/R$45,"") -> 0.006104826 | V27: =IFERROR(S27/S$45,"") | W27: =IFERROR(T27/T$45,"") -> 0.006104826
E28: Nha Trang | F28: =NhaTrang!F13 -> 7.3 | G28: =NhaTrang!G13 -> 14.535 | H28: =NhaTrang!H13 -> 17.55 | I28: =NhaTrang!I13 -> 27.4 | J28: =NhaTrang!J13 -> 13.45 | K28: =NhaTrang!K13 -> 14.45 | L28: =NhaTrang!L13 -> 14.425 | M28: =NhaTrang!M13 -> 15.525 | ... Q28: =NhaTrang!Q13 -> 40.65 | R28: =SUMIFS($F28:$Q28,$F$7:$Q$7,"A") -> 353.465 | S28: =SUMIFS($F28:$Q28,$F$7:$Q$7,"B") -> 0 | T28: =SUM(R28:S28) -> 353.465 | U28: =IFERROR(R28/R$45,"") -> 0.0077803261 | V28: =IFERROR(S28/S$45,"") | W28: =IFERROR(T28/T$45,"") -> 0.0077803261
E29: Thạch Thất | F29: =ThachThat!F12 -> 0 | G29: =ThachThat!G12 -> 0 | H29: =ThachThat!H12 -> 0 | I29: =ThachThat!I12 -> 0 | J29: =ThachThat!J12 -> 0 | K29: =ThachThat!K12 -> 0 | L29: =ThachThat!L12 -> 0 | M29: =ThachThat!M12 -> 0 | ... Q29: =ThachThat!Q12 -> 84 | R29: =SUMIFS($F29:$Q29,$F$7:$Q$7,"A") -> 693.3 | S29: =SUMIFS($F29:$Q29,$F$7:$Q$7,"B") -> 0 | T29: =SUM(R29:S29) -> 693.3 | U29: =IFERROR(R29/R$45,"") -> 0.015260634 | V29: =IFERROR(S29/S$45,"") | W29: =IFERROR(T29/T$45,"") -> 0.015260634
D30: Mammo X-Quang | F30: =SUBTOTAL(9,F31:F34) -> 14.64 | G30: =SUBTOTAL(9,G31:G34) -> 20.525 | H30: =SUBTOTAL(9,H31:H34) -> 40.05 | I30: =SUBTOTAL(9,I31:I34) -> 39.3 | J30: =SUBTOTAL(9,J31:J34) -> 72.315 | K30: =SUBTOTAL(9,K31:K34) -> 57.515 | L30: =SUBTOTAL(9,L31:L34) -> 43.1 | M30: =SUBTOTAL(9,M31:M34) -> 42.3 | ... Q30: =SUBTOTAL(9,Q31:Q34) -> 27.225 | R30: =SUMIFS($F30:$Q30,$F$7:$Q$7,"A") -> 495.5856 | S30: =SUMIFS($F30:$Q30,$F$7:$Q$7,"B") -> 0 | T30: =SUM(R30:S30) -> 495.5856 | U30: =IFERROR(R30/R$45,"") -> 0.010908626 | V30: =IFERROR(S30/S$45,"") | W30: =IFERROR(T30/T$45,"") -> 0.010908626
E31: Hải Dương | F31: =HaiDuong!F43 -> 4 | G31: =HaiDuong!G43 -> 9.5 | H31: =HaiDuong!H43 -> 8.5 | I31: =HaiDuong!I43 -> 20.5 | J31: =HaiDuong!J43 -> 11 | K31: =HaiDuong!K43 -> 10.8 | L31: =HaiDuong!L43 -> 10.5 | M31: =HaiDuong!M43 -> 14 | ... Q31: =HaiDuong!Q43 -> 8 | R31: =SUMIFS($F31:$Q31,$F$7:$Q$7,"A") -> 124.3 | S31: =SUMIFS($F31:$Q31,$F$7:$Q$7,"B") -> 0 | T31: =SUM(R31:S31) -> 124.3 | U31: =IFERROR(R31/R$45,"") -> 0.0027360404 | V31: =IFERROR(S31/S$45,"") | W31: =IFERROR(T31/T$45,"") -> 0.0027360404
E32: Cà Mau | F32: =CaMau!F13 -> 8 | G32: =CaMau!G13 -> 8 | H32: =CaMau!H13 -> 25.5 | I32: =CaMau!I13 -> 15.5 | J32: =CaMau!J13 -> 16.8 | K32: =CaMau!K13 -> 39.3 | L32: =CaMau!L13 -> 19.4 | M32: =CaMau!M13 -> 24.5 | ... Q32: =CaMau!Q13 -> 13.4 | R32: =SUMIFS($F32:$Q32,$F$7:$Q$7,"A") -> 222.1 | S32: =SUMIFS($F32:$Q32,$F$7:$Q$7,"B") -> 0 | T32: =SUM(R32:S32) -> 222.1 | U32: =IFERROR(R32/R$45,"") -> 0.0048887738 | V32: =IFERROR(S32/S$45,"") | W32: =IFERROR(T32/T$45,"") -> 0.0048887738
E33: Yết Kiêu | F33: =YetKieu!F13 -> 0.55 | G33: =YetKieu!G13 -> 1.925 | H33: =YetKieu!H13 -> 2.75 | I33: =YetKieu!I13 -> 0.55 | J33: =YetKieu!J13 -> 43.14 | K33: =YetKieu!K13 -> 5.49 | L33: =YetKieu!L13 -> 8.8 | M33: =YetKieu!M13 -> 1.05 | ... Q33: =YetKieu!Q13 -> 2.315 | R33: =SUMIFS($F33:$Q33,$F$7:$Q$7,"A") -> 79.0656 | S33: =SUMIFS($F33:$Q33,$F$7:$Q$7,"B") -> 0 | T33: =SUM(R33:S33) -> 79.0656 | U33: =IFERROR(R33/R$45,"") -> 0.0017403594 | V33: =IFERROR(S33/S$45,"") | W33: =IFERROR(T33/T$45,"") -> 0.0017403594
E34: Nha Trang | F34: =NhaTrang!F14 -> 2.09 | G34: =NhaTrang!G14 -> 1.1 | H34: =NhaTrang!H14 -> 3.3 | I34: =NhaTrang!I14 -> 2.75 | J34: =NhaTrang!J14 -> 1.375 | K34: =NhaTrang!K14 -> 1.925 | L34: =NhaTrang!L14 -> 4.4 | M34: =NhaTrang!M14 -> 2.75 | ... Q34: =NhaTrang!Q14 -> 3.51 | R34: =SUMIFS($F34:$Q34,$F$7:$Q$7,"A") -> 70.12 | S34: =SUMIFS($F34:$Q34,$F$7:$Q$7,"B") -> 0 | T34: =SUM(R34:S34) -> 70.12 | U34: =IFERROR(R34/R$45,"") -> 0.0015434526 | V34: =IFERROR(S34/S$45,"") | W34: =IFERROR(T34/T$45,"") -> 0.0015434526
D35: X-Quang | F35: =SUBTOTAL(9,F36:F39) -> 10.225 | G35: =SUBTOTAL(9,G36:G39) -> 15.75 | H35: =SUBTOTAL(9,H36:H39) -> 29.157 | I35: =SUBTOTAL(9,I36:I39) -> 35.855 | J35: =SUBTOTAL(9,J36:J39) -> 29.24 | K35: =SUBTOTAL(9,K36:K39) -> 33.59 | L35: =SUBTOTAL(9,L36:L39) -> 38.19 | M35: =SUBTOTAL(9,M36:M39) -> 28.62 | ... Q35: =SUBTOTAL(9,Q36:Q39) -> 28.77 | R35: =SUMIFS($F35:$Q35,$F$7:$Q$7,"A") -> 360.407 | S35: =SUMIFS($F35:$Q35,$F$7:$Q$7,"B") -> 0 | T35: =SUM(R35:S35) -> 360.407 | U35: =IFERROR(R35/R$45,"") -> 0.0079331305 | V35: =IFERROR(S35/S$45,"") | W35: =IFERROR(T35/T$45,"") -> 0.0079331305
E36: Hải Dương | F36: =HaiDuong!F45 -> 8.35 | G36: =HaiDuong!G45 -> 11 | H36: =HaiDuong!H45 -> 23.6 | I36: =HaiDuong!I45 -> 30.75 | J36: =HaiDuong!J45 -> 23.1 | K36: =HaiDuong!K45 -> 25.15 | L36: =HaiDuong!L45 -> 31.35 | M36: =HaiDuong!M45 -> 23.75 | ... Q36: =HaiDuong!Q45 -> 22.5 | R36: =SUMIFS($F36:$Q36,$F$7:$Q$7,"A") -> 278.5 | S36: =SUMIFS($F36:$Q36,$F$7:$Q$7,"B") -> 0 | T36: =SUM(R36:S36) -> 278.5 | U36: =IFERROR(R36/R$45,"") -> 0.0061302274 | V36: =IFERROR(S36/S$45,"") | W36: =IFERROR(T36/T$45,"") -> 0.0061302274
E37: Thái Nguyên | F37: =ThaiNguyen!F15 -> 0 | G37: =ThaiNguyen!G15 -> 0 | H37: =ThaiNguyen!H15 -> 0 | I37: =ThaiNguyen!I15 -> 0 | J37: =ThaiNguyen!J15 -> 0 | K37: =ThaiNguyen!K15 -> 0 | L37: =ThaiNguyen!L15 -> 0 | M37: =ThaiNguyen!M15 -> 0 | ... Q37: =ThaiNguyen!Q15 -> 1.65 | R37: =SUMIFS($F37:$Q37,$F$7:$Q$7,"A") -> 8.1 | S37: =SUMIFS($F37:$Q37,$F$7:$Q$7,"B") -> 0 | T37: =SUM(R37:S37) -> 8.1 | U37: =IFERROR(R37/R$45,"") -> 0.00017829387 | V37: =IFERROR(S37/S$45,"") | W37: =IFERROR(T37/T$45,"") -> 0.00017829387
E38: Thái Bình | F38: =ThaiBinh!F15 -> 0 | G38: =ThaiBinh!G15 -> 0 | H38: =ThaiBinh!H15 -> 0 | I38: =ThaiBinh!I15 -> 0 | J38: =ThaiBinh!J15 -> 0 | K38: =ThaiBinh!K15 -> 0 | L38: =ThaiBinh!L15 -> 0 | M38: =ThaiBinh!M15 -> 0 | ... Q38: =ThaiBinh!Q15 -> 2.2 | R38: =SUMIFS($F38:$Q38,$F$7:$Q$7,"A") -> 6.15 | S38: =SUMIFS($F38:$Q38,$F$7:$Q$7,"B") -> 0 | T38: =SUM(R38:S38) -> 6.15 | U38: =IFERROR(R38/R$45,"") -> 0.00013537127 | V38: =IFERROR(S38/S$45,"") | W38: =IFERROR(T38/T$45,"") -> 0.00013537127
E39: Yết Kiêu | F39: =YetKieu!F15 -> 1.875 | G39: =YetKieu!G15 -> 4.75 | H39: =YetKieu!H15 -> 5.557 | I39: =YetKieu!I15 -> 5.105 | J39: =YetKieu!J15 -> 6.14 | K39: =YetKieu!K15 -> 8.44 | L39: =YetKieu!L15 -> 6.84 | M39: =YetKieu!M15 -> 4.87 | ... Q39: =YetKieu!Q15 -> 2.42 | R39: =SUMIFS($F39:$Q39,$F$7:$Q$7,"A") -> 67.657 | S39: =SUMIFS($F39:$Q39,$F$7:$Q$7,"B") -> 0 | T39: =SUM(R39:S39) -> 67.657 | U39: =IFERROR(R39/R$45,"") -> 0.001489238 | V39: =IFERROR(S39/S$45,"") | W39: =IFERROR(T39/T$45,"") -> 0.001489238
D40: Siêu âm | F40: =SUBTOTAL(9,F41:F42) -> 5.7 | G40: =SUBTOTAL(9,G41:G42) -> 11.1 | H40: =SUBTOTAL(9,H41:H42) -> 11.3 | I40: =SUBTOTAL(9,I41:I42) -> 9.3 | J40: =SUBTOTAL(9,J41:J42) -> 7.25 | K40: =SUBTOTAL(9,K41:K42) -> 6.55 | L40: =SUBTOTAL(9,L41:L42) -> 13.9 | M40: =SUBTOTAL(9,M41:M42) -> 7.45 | ... Q40: =SUBTOTAL(9,Q41:Q42) -> 15.95 | R40: =SUMIFS($F40:$Q40,$F$7:$Q$7,"A") -> 131.54 | S40: =SUMIFS($F40:$Q40,$F$7:$Q$7,"B") -> 0 | T40: =SUM(R40:S40) -> 131.54 | U40: =IFERROR(R40/R$45,"") -> 0.0028954043 | V40: =IFERROR(S40/S$45,"") | W40: =IFERROR(T40/T$45,"") -> 0.0028954043
E41: Hải Dương | F41: =HaiDuong!F46 -> 5 | G41: =HaiDuong!G46 -> 11.1 | H41: =HaiDuong!H46 -> 10.6 | I41: =HaiDuong!I46 -> 9.05 | J41: =HaiDuong!J46 -> 7.15 | K41: =HaiDuong!K46 -> 6.55 | L41: =HaiDuong!L46 -> 13.9 | M41: =HaiDuong!M46 -> 7.45 | ... Q41: =HaiDuong!Q46 -> 11.3 | R41: =SUMIFS($F41:$Q41,$F$7:$Q$7,"A") -> 114.9 | S41: =SUMIFS($F41:$Q41,$F$7:$Q$7,"B") -> 0 | T41: =SUM(R41:S41) -> 114.9 | U41: =IFERROR(R41/R$45,"") -> 0.0025291315 | V41: =IFERROR(S41/S$45,"") | W41: =IFERROR(T41/T$45,"") -> 0.0025291315
E42: Yết Kiêu | F42: =YetKieu!F16 -> 0.7 | G42: =YetKieu!G16 -> 0 | H42: =YetKieu!H16 -> 0.7 | I42: =YetKieu!I16 -> 0.25 | J42: =YetKieu!J16 -> 0.1 | K42: =YetKieu!K16 -> 0 | L42: =YetKieu!L16 -> 0 | M42: =YetKieu!M16 -> 0 | ... Q42: =YetKieu!Q16 -> 4.65 | R42: =SUMIFS($F42:$Q42,$F$7:$Q$7,"A") -> 16.64 | S42: =SUMIFS($F42:$Q42,$F$7:$Q$7,"B") -> 0 | T42: =SUM(R42:S42) -> 16.64 | U42: =IFERROR(R42/R$45,"") -> 0.00036627283 | V42: =IFERROR(S42/S$45,"") | W42: =IFERROR(T42/T$45,"") -> 0.00036627283
C43: Tổng- Chẩn đoán hình ảnh | F43: =SUBTOTAL(9,F13:F42) -> 1481.585 | G43: =SUBTOTAL(9,G13:G42) -> 3069.64 | H43: =SUBTOTAL(9,H13:H42) -> 3894.769 | I43: =SUBTOTAL(9,I13:I42) -> 3957.0754 | J43: =SUBTOTAL(9,J13:J42) -> 4260.1387 | K43: =SUBTOTAL(9,K13:K42) -> 4547.1528 | L43: =SUBTOTAL(9,L13:L42) -> 4410.036 | M43: =SUBTOTAL(9,M13:M42) -> 3999.461 | ... Q43: =SUBTOTAL(9,Q13:Q42) -> 3605.871 | R43: =SUMIFS($F43:$Q43,$F$7:$Q$7,"A") -> 45366.945 | S43: =SUMIFS($F43:$Q43,$F$7:$Q$7,"B") -> 0 | T43: =SUM(R43:S43) -> 45366.945 | U43: =IFERROR(R43/R$45,"") -> 0.99859852 | V43: =IFERROR(S43/S$45,"") | W43: =IFERROR(T43/T$45,"") -> 0.99859852
C44: Tổng- Khác | F44: =SUM(HaiDuong!F48,CaMau!F18,ThanhHoa!F18,ThaiNguyen!F18,YetKieu!F17,NhaTrang!F15) -> 0 | G44: =SUM(HaiDuong!G48,CaMau!G18,ThanhHoa!G18,ThaiNguyen!G18,YetKieu!G17,NhaTrang!G15) -> 1.85 | H44: =SUM(HaiDuong!H48,CaMau!H18,ThanhHoa!H18,ThaiNguyen!H18,YetKieu!H17,NhaTrang!H15) -> 1.05 | I44: =SUM(HaiDuong!I48,CaMau!I18,ThanhHoa!I18,ThaiNguyen!I18,YetKieu!I17,NhaTrang!I15) -> 6.6 | J44: =SUM(HaiDuong!J48,CaMau!J18,ThanhHoa!J18,ThaiNguyen!J18,YetKieu!J17,NhaTrang!J15) -> 4.9 | K44: =SUM(HaiDuong!K48,CaMau!K18,ThanhHoa!K18,ThaiNguyen!K18,YetKieu!K17,NhaTrang!K15) -> 9.3 | L44: =SUM(HaiDuong!L48,CaMau!L18,ThanhHoa!L18,ThaiNguyen!L18,YetKieu!L17,NhaTrang!L15) -> 6.8 | M44: =SUM(HaiDuong!M48,CaMau!M18,ThanhHoa!M18,ThaiNguyen!M18,YetKieu!M17,NhaTrang!M15) -> 5.95 | ... Q44: =SUM(HaiDuong!Q48,CaMau!Q18,ThanhHoa!Q18,ThaiNguyen!Q18,YetKieu!Q17,NhaTrang!Q15) -> 5.65 | R44: =SUMIFS($F44:$Q44,$F$7:$Q$7,"A") -> 63.67 | S44: =SUMIFS($F44:$Q44,$F$7:$Q$7,"B") -> 0 | T44: =SUM(R44:S44) -> 63.67 | U44: =IFERROR(R44/R$45,"") -> 0.0014014778 | V44: =IFERROR(S44/S$45,"") | W44: =IFERROR(T44/T$45,"") -> 0.0014014778
B45: Tổng- Doanh thu | F45: =SUM(F43:F44) -> 1481.585 | G45: =SUM(G43,G44) -> 3071.49 | H45: =SUM(H43,H44) -> 3895.819 | I45: =SUM(I43,I44) -> 3963.6754 | J45: =SUM(J43,J44) -> 4265.0387 | K45: =SUM(K43,K44) -> 4556.4528 | L45: =SUM(L43,L44) -> 4416.836 | M45: =SUM(M43,M44) -> 4005.411 | N45: =SUM(N43,N44) -> 4807.8152 | ... Q45: =SUM(Q43,Q44) -> 3611.521 | R45: =SUMIFS($F45:$Q45,$F$7:$Q$7,"A") -> 45430.615 | S45: =SUMIFS($F45:$Q45,$F$7:$Q$7,"B") -> 0 | T45: =SUM(R45:S45) -> 45430.615 | U45: =IFERROR(R45/R$45,"") -> 1 | V45: =IFERROR(S45/S$45,"") | W45: =IFERROR(T45/T$45,"") -> 1
B46: Giảm trừ doanh thu | F46: =SUM(HaiDuong!F50,CaMau!F20,ThanhHoa!F20,ThaiNguyen!F20) -> 0.1 | G46: =SUM(HaiDuong!G50,CaMau!G20,ThanhHoa!G20,ThaiNguyen!G20) -> 26.36 | H46: =SUM(HaiDuong!H50,CaMau!H20,ThanhHoa!H20,ThaiNguyen!H20) -> 49.46 | I46: =SUM(HaiDuong!I50,CaMau!I20,ThanhHoa!I20,ThaiNguyen!I20) -> 43.69 | J46: =SUM(HaiDuong!J50,CaMau!J20,ThanhHoa!J20,ThaiNguyen!J20) -> 65.38 | K46: =SUM(HaiDuong!K50,CaMau!K20,ThanhHoa!K20,ThaiNguyen!K20) -> 57.76 | L46: =SUM(HaiDuong!L50,CaMau!L20,ThanhHoa!L20,ThaiNguyen!L20) -> 54.66 | M46: =SUM(HaiDuong!M50,CaMau!M20,ThanhHoa!M20,ThaiNguyen!M20) -> 83.46 | ... Q46: =SUM(HaiDuong!Q50,CaMau!Q20,ThanhHoa!Q20,ThaiNguyen!Q20) -> 111.6 | R46: =SUMIFS($F46:$Q46,$F$7:$Q$7,"A") -> 757.135 | S46: =SUMIFS($F46:$Q46,$F$7:$Q$7,"B") -> 0 | T46: =SUM(R46:S46) -> 757.135 | U46: =IFERROR(R46/R$45,"") -> 0.016665744 | V46: =IFERROR(S46/S$45,"") | W46: =IFERROR(T46/T$45,"") -> 0.016665744
...

Sheet Conso BS
B5: BÁO CÁO TÌNH HÌNH TÀI CHÍNH HỢP NHẤT
B6: Tại | C6: 31.12.2025
E8: Cuối tháng
B9: VND triệu | E9: 1 | F9: 2 | G9: 3 | H9: 4 | I9: 5 | J9: 6 | K9: 7 | L9: 8 | M9: 9 | N9: 10 | O9: 11 | P9: 12
C10: Tài sản ngắn hạn
D11: Tiền và tương đương tiền
D12: Phải thu khách hàng | E12: =SUBTOTAL(9,E13:E14) -> 0 | F12: =SUBTOTAL(9,F13:F14) -> 0 | G12: =SUBTOTAL(9,G13:G14) -> 0 | H12: =SUBTOTAL(9,H13:H14) -> 0 | I12: =SUBTOTAL(9,I13:I14) -> 0 | J12: =SUBTOTAL(9,J13:J14) -> 0 | K12: =SUBTOTAL(9,K13:K14) -> 0 | L12: =SUBTOTAL(9,L13:L14) -> 0 | ... P12: =SUBTOTAL(9,P13:P14) -> 0
D13: Trong hạn thanh toán
D14: Quá hạn thanh toán
D15: Ứng trước cho nhà cung cấp
D16: Chi phí chờ phân bổ
D17: Thuế GTGT được khấu trừ
C18: Tổng tài sản ngắn hạn | E18: =SUBTOTAL(9,E11:E17) -> 0 | F18: =SUBTOTAL(9,F11:F17) -> 0 | G18: =SUBTOTAL(9,G11:G17) -> 0 | H18: =SUBTOTAL(9,H11:H17) -> 0 | I18: =SUBTOTAL(9,I11:I17) -> 0 | J18: =SUBTOTAL(9,J11:J17) -> 0 | K18: =SUBTOTAL(9,K11:K17) -> 0 | L18: =SUBTOTAL(9,L11:L17) -> 0 | ... P18: =SUBTOTAL(9,P11:P17) -> 0
C19: Tài sản dài hạn
D20: Tài sản cố định
D21: Chi phí chờ phân bổ
C22: Tổng tài sản dài hạn | E22: =SUBTOTAL(9,E20:E21) -> 0 | F22: =SUBTOTAL(9,F20:F21) -> 0 | G22: =SUBTOTAL(9,G20:G21) -> 0 | H22: =SUBTOTAL(9,H20:H21) -> 0 | I22: =SUBTOTAL(9,I20:I21) -> 0 | J22: =SUBTOTAL(9,J20:J21) -> 0 | K22: =SUBTOTAL(9,K20:K21) -> 0 | L22: =SUBTOTAL(9,L20:L21) -> 0 | ... P22: =SUBTOTAL(9,P20:P21) -> 0
B23: TỔNG TÀI SẢN | E23: =SUBTOTAL(9,E11:E22) -> 0 | F23: =SUBTOTAL(9,F11:F22) -> 0 | G23: =SUBTOTAL(9,G11:G22) -> 0 | H23: =SUBTOTAL(9,H11:H22) -> 0 | I23: =SUBTOTAL(9,I11:I22) -> 0 | J23: =SUBTOTAL(9,J11:J22) -> 0 | K23: =SUBTOTAL(9,K11:K22) -> 0 | L23: =SUBTOTAL(9,L11:L22) -> 0 | ... P23: =SUBTOTAL(9,P11:P22) -> 0
C24: Nợ ngắn hạn
D25: Phải trả nhà cung cấp | E25: =SUBTOTAL(9,E26:E27) -> 0 | F25: =SUBTOTAL(9,F26:F27) -> 0 | G25: =SUBTOTAL(9,G26:G27) -> 0 | H25: =SUBTOTAL(9,H26:H27) -> 0 | I25: =SUBTOTAL(9,I26:I27) -> 0 | J25: =SUBTOTAL(9,J26:J27) -> 0 | K25: =SUBTOTAL(9,K26:K27) -> 0 | L25: =SUBTOTAL(9,L26:L27) -> 0 | ... P25: =SUBTOTAL(9,P26:P27) -> 0
D26: Trong hạn thanh toán
D27: Quá hạn thanh toán
D28: Thuế GTGT & thuế khác phải trả
D29: Phải trả khác
D30: Vay và nợ ngắn hạn
C31: Tổng nợ ngắn hạn | E31: =SUBTOTAL(9,E25:E30) -> 0 | F31: =SUBTOTAL(9,F25:F30) -> 0 | G31: =SUBTOTAL(9,G25:G30) -> 0 | H31: =SUBTOTAL(9,H25:H30) -> 0 | I31: =SUBTOTAL(9,I25:I30) -> 0 | J31: =SUBTOTAL(9,J25:J30) -> 0 | K31: =SUBTOTAL(9,K25:K30) -> 0 | L31: =SUBTOTAL(9,L25:L30) -> 0 | ... P31: =SUBTOTAL(9,P25:P30) -> 0
C32: Nợ dài hạn
D33: Vay và nợ dài hạn
C34: Tổng nợ dài hạn | E34: =SUBTOTAL(9,E33) -> 0 | F34: =SUBTOTAL(9,F33) -> 0 | G34: =SUBTOTAL(9,G33) -> 0 | H34: =SUBTOTAL(9,H33) -> 0 | I34: =SUBTOTAL(9,I33) -> 0 | J34: =SUBTOTAL(9,J33) -> 0 | K34: =SUBTOTAL(9,K33) -> 0 | L34: =SUBTOTAL(9,L33) -> 0 | ... P34: =SUBTOTAL(9,P33) -> 0
B35: TỔNG NỢ | E35: =SUBTOTAL(9,E25:E34) -> 0 | F35: =SUBTOTAL(9,F25:F34) -> 0 | G35: =SUBTOTAL(9,G25:G34) -> 0 | H35: =SUBTOTAL(9,H25:H34) -> 0 | I35: =SUBTOTAL(9,I25:I34) -> 0 | J35: =SUBTOTAL(9,J25:J34) -> 0 | K35: =SUBTOTAL(9,K25:K34) -> 0 | L35: =SUBTOTAL(9,L25:L34) -> 0 | ... P35: =SUBTOTAL(9,P25:P34) -> 0
C36: Vốn chủ sở hữu
C37: Thặng dư vốn góp
C38: Lợi nhuận giữ lại | E38: =SUBTOTAL(9,E39:E40) -> 0 | F38: =SUBTOTAL(9,F39:F40) -> 0 | G38: =SUBTOTAL(9,G39:G40) -> 0 | H38: =SUBTOTAL(9,H39:H40) -> 0 | I38: =SUBTOTAL(9,I39:I40) -> 0 | J38: =SUBTOTAL(9,J39:J40) -> 0 | K38: =SUBTOTAL(9,K39:K40) -> 0 | L38: =SUBTOTAL(9,L39:L40) -> 0 | ... P38: =SUBTOTAL(9,P39:P40) -> 0
D39: Lợi nhuận giữ lại các năm trước
D40: Lợi nhuận giữ lại năm hiện tại
B41: TỔNG VỐN CHỦ SỞ HỮU | E41: =SUBTOTAL(9,E36:E40) -> 0 | F41: =SUBTOTAL(9,F36:F40) -> 0 | G41: =SUBTOTAL(9,G36:G40) -> 0 | H41: =SUBTOTAL(9,H36:H40) -> 0 | I41: =SUBTOTAL(9,I36:I40) -> 0 | J41: =SUBTOTAL(9,J36:J40) -> 0 | K41: =SUBTOTAL(9,K36:K40) -> 0 | L41: =SUBTOTAL(9,L36:L40) -> 0 | ... P41: =SUBTOTAL(9,P36:P40) -> 0
B42: TỔNG NGUỒN VỐN | E42: =E41+E35 -> 0 | F42: =F41+F35 -> 0 | G42: =G41+G35 -> 0 | H42: =H41+H35 -> 0 | I42: =I41+I35 -> 0 | J42: =J41+J35 -> 0 | K42: =K41+K35 -> 0 | L42: =L41+L35 -> 0 | ... P42: =P41+P35 -> 0
E43: =E23-E42 -> 0 | F43: =F23-F42 -> 0 | G43: =G23-G42 -> 0 | H43: =H23-H42 -> 0 | I43: =I23-I42 -> 0 | J43: =J23-J42 -> 0 | K43: =K23-K42 -> 0 | L43: =L23-L42 -> 0 | ... P43: =P23-P42 -> 0

Sheet HaiDuong
B6: BÁO CÁO KẾT QUẢ HOẠT ĐỘNG KINH DOANH CHI NHÁNH
B7: HẢI DƯƠNG | F7: A | G7: A | H7: A | I7: A | J7: A | K7: A | L7: A | M7: A | N7: A | O7: A | P7: A | Q7: A
B8: Năm tài chính 2025 | F8: Tháng | R8: ------------------Tổng-------------------- | U8: ------%Doanh thu------- | X8: ------------vs-------------- | Z8: ----------------Forecast--------------------
B9: VND triệu | F9: 1 | G9: 2 | H9: 3 | I9: 4 | J9: 5 | K9: 6 | L9: 7 | M9: 8 | N9: 9 | O9: 10 | P9: 11 | Q9: 12 | R9: Year to date | S9: Year to go | T9: LATEST ESTIMATE | U9: YTD | V9: YTG | W9: LE | X9: Last month | Y9: Last year | Z9: Assumption | AA9: Note | AB9: 2026F
B11: Đơn giá bán trung bình
E12: MRI | F12: =F42*10^6/F18 -> 1869260.7 | G12: =G42*10^6/G18 -> 1906965.2 | H12: =H42*10^6/H18 -> 1878260.9 | I12: =I42*10^6/I18 -> 1863197 | J12: =J42*10^6/J18 -> 1858315.3 | K12: =K42*10^6/K18 -> 1834324.9 | L12: =L42*10^6/L18 -> 1882405.3 | M12: =M42*10^6/M18 -> 1889385.5 | ... P12: =P42*10^6/P18 -> 1913761.5 | Q12: 1827593.6 | T12: =T42*10^6/T18 -> 1876497.6 | AB12: =T12 -> 1876497.6
E13: Mammo X-Quang | F13: =F43*10^6/F19 -> 571428.57 | G13: =G43*10^6/G19 -> 593750 | H13: =H43*10^6/H19 -> 500000 | I13: =I43*10^6/I19 -> 554054.05 | J13: =J43*10^6/J19 -> 500000 | K13: =K43*10^6/K19 -> 600000 | L13: =L43*10^6/L19 -> 500000 | M13: =M43*10^6/M19 -> 500000 | ... P13: =P43*10^6/P19 -> 500000 | Q13: 500000 | T13: =T43*10^6/T19 -> 524472.57 | AB13: =T13 -> 524472.57
E14: CT | F14: =F44*10^6/F20 -> 1164814.8 | G14: =G44*10^6/G20 -> 1195804.2 | H14: =H44*10^6/H20 -> 1201807.2 | I14: =I44*10^6/I20 -> 1191542.3 | J14: =J44*10^6/J20 -> 1160447.8 | K14: =K44*10^6/K20 -> 1117924.5 | L14: =L44*10^6/L20 -> 1166666.7 | M14: =M44*10^6/M20 -> 1223684.2 | ... P14: =P44*10^6/P20 -> 1286747 | Q14: 1224770.6 | T14: =T44*10^6/T20 -> 1189934.8 | AB14: =T14 -> 1189934.8
E15: X-Quang | F15: =F45*10^6/F21 -> 143965.52 | G15: =G45*10^6/G21 -> 132530.12 | H15: =H45*10^6/H21 -> 160544.22 | I15: =I45*10^6/I21 -> 134868.42 | J15: =J45*10^6/J21 -> 137500 | K15: =K45*10^6/K21 -> 133776.6 | L15: =L45*10^6/L21 -> 154433.5 | M15: =M45*10^6/M21 -> 153225.81 | ... P15: =P45*10^6/P21 -> 148395.72 | Q15: 150000 | T15: =T45*10^6/T21 -> 148296.06 | AB15: =T15 -> 148296.06
E16: Siêu âm | F16: =F46*10^6/F22 -> 138888.89 | G16: =G46*10^6/G22 -> 154166.67 | H16: =H46*10^6/H22 -> 158208.96 | I16: =I46*10^6/I22 -> 158771.93 | J16: =J46*10^6/J22 -> 170238.1 | K16: =K46*10^6/K22 -> 172368.42 | L16: =L46*10^6/L22 -> 163529.41 | M16: =M46*10^6/M22 -> 161956.52 | ... P16: =P46*10^6/P22 -> 159090.91 | Q16: 161428.57 | T16: =T46*10^6/T22 -> 160027.86 | AB16: =T16 -> 160027.86
B17: Số ca
E18: MRI | F18: 257 | G18: 402 | H18: 460 | I18: 538 | J18: 463 | K18: 437 | L18: 449 | M18: 358 | N18: 373 | O18: 353 | P18: 327 | Q18: 374 | T18: =SUM(F18:Q18) -> 4791 | AB18: =AB95 -> 5440
E19: Mammo X-Quang | F19: 7 | G19: 16 | H19: 17 | I19: 37 | J19: 22 | K19: 18 | L19: 21 | M19: 28 | N19: 20 | O19: 18 | P19: 17 | Q19: 16 | T19: =SUM(F19:Q19) -> 237 | AB19: =AB96 -> 444
E20: CT | F20: 108 | G20: 143 | H20: 166 | I20: 201 | J20: 134 | K20: 106 | L20: 81 | M20: 76 | N20: 82 | O20: 92 | P20: 83 | Q20: 109 | T20: =SUM(F20:Q20) -> 1381 | AB20: =AB97 -> 2332.8
E21: X-Quang | F21: 58 | G21: 83 | H21: 147 | I21: 228 | J21: 168 | K21: 188 | L21: 203 | M21: 155 | N21: 167 | O21: 144 | P21: 187 | Q21: 150 | T21: =SUM(F21:Q21) -> 1878 | AB21: =AB98 -> 2736
E22: Siêu âm | F22: 36 | G22: 72 | H22: 67 | I22: 57 | J22: 42 | K22: 38 | L22: 85 | M22: 46 | N22: 79 | O22: 82 | P22: 44 | Q22: 70 | T22: =SUM(F22:Q22) -> 718 | AB22: =AB99 -> 1020
B23: Đơn giá chi phí trung bình
D24: Vật tư tiêu hao
E25: MRI | R25: 66943.206
E26: Mammo X-Quang | R26: 32967.486
E27: CT | R27: 73748.968
E28: X-Quang | R28: 22816.038
E29: Siêu âm | R29: 7348.1512
D30: Chi phí đọc kết quả online
E31: MRI
E32: Mammo X-Quang
E33: CT
E34: X-Quang
E35: Siêu âm
D36: Tiền thuốc
D37: Hoa hồng cho bác sĩ
D38: Hoa hồng nhân viên
D39: Truyền thông marketing
B40: Doanh thu
D41: Chẩn đoán hình ảnh
E42: MRI | F42: =480400000/(10^6) -> 480.4 | G42: =766600000/(10^6) -> 766.6 | H42: =864000000/(10^6) -> 864 | I42: =1002400000/(10^6) -> 1002.4 | J42: =860400000/(10^6) -> 860.4 | K42: =801600000/(10^6) -> 801.6 | L42: =845200000/(10^6) -> 845.2 | M42: =676400000/(10^6) -> 676.4 | N42: =707300000/(10^6) -> 707.3 | O42: =659800000/(10^6) -> 659.8 | P42: =625800000/(10^6) -> 625.8 | Q42: 700.4 | R42: =SUMIFS($F42:$Q42,$F$7:$Q$7,"A") -> 8990.3 | S42: =SUMIFS($F42:$Q42,$F$7:$Q$7,"B") -> 0 | T42: =SUM(R42:S42) -> 8990.3 | U42: =IFERROR(R42/R$47,"") -> 0.80621094 | V42: =IFERROR(S42/S$47,"") | W42: =IFERROR(T42/T$47,"") -> 0.80621094 | Z42: 0.05 | AA42: vs 2025 | AB42: =AB12*AB18/10^6 -> 10208.147
E43: Mammo X-Quang | F43: 4 | G43: 9.5 | H43: 8.5 | I43: 20.5 | J43: 11 | K43: 10.8 | L43: 10.5 | M43: 14 | N43: 10 | O43: 9 | P43: 8.5 | Q43: 8 | R43: =SUMIFS($F43:$Q43,$F$7:$Q$7,"A") -> 124.3 | S43: =SUMIFS($F43:$Q43,$F$7:$Q$7,"B") -> 0 | T43: =SUM(R43:S43) -> 124.3 | U43: =IFERROR(R43/R$47,"") -> 0.011146682 | V43: =IFERROR(S43/S$47,"") | W43: =IFERROR(T43/T$47,"") -> 0.011146682 | Z43: 0.05 | AA43: vs 2025 | AB43: =AB13*AB19/10^6 -> 232.86582
E44: CT | F44: =125800000/(10^6) -> 125.8 | G44: =171000000/(10^6) -> 171 | H44: =199500000/(10^6) -> 199.5 | I44: =239500000/(10^6) -> 239.5 | J44: =155500000/(10^6) -> 155.5 | K44: =118500000/(10^6) -> 118.5 | L44: =94500000/(10^6) -> 94.5 | M44: =93000000/(10^6) -> 93 | N44: =91000000/(10^6) -> 91 | O44: =113300000/(10^6) -> 113.3 | P44: =106800000/(10^6) -> 106.8 | Q44: 134.9 | R44: =SUMIFS($F44:$Q44,$F$7:$Q$7,"A") -> 1643.3 | S44: =SUMIFS($F44:$Q44,$F$7:$Q$7,"B") -> 0 | T44: =SUM(R44:S44) -> 1643.3 | U44: =IFERROR(R44/R$47,"") -> 0.14736398 | V44: =IFERROR(S44/S$47,"") | W44: =IFERROR(T44/T$47,"") -> 0.14736398 | Z44: 0.05 | AA44: vs 2025 | AB44: =AB14*AB20/10^6 -> 2775.88
E45: X-Quang | F45: =8350000/(10^6) -> 8.35 | G45: =11000000/(10^6) -> 11 | H45: =23600000/(10^6) -> 23.6 | I45: =30750000/(10^6) -> 30.75 | J45: =23100000/(10^6) -> 23.1 | K45: =25150000/(10^6) -> 25.15 | L45: =31350000/(10^6) -> 31.35 | M45: =23750000/(10^6) -> 23.75 | N45: =28500000/(10^6) -> 28.5 | O45: =22700000/(10^6) -> 22.7 | P45: =27750000/(10^6) -> 27.75 | Q45: 22.5 | R45: =SUMIFS($F45:$Q45,$F$7:$Q$7,"A") -> 278.5 | S45: =SUMIFS($F45:$Q45,$F$7:$Q$7,"B") -> 0 | T45: =SUM(R45:S45) -> 278.5 | U45: =IFERROR(R45/R$47,"") -> 0.024974667 | V45: =IFERROR(S45/S$47,"") | W45: =IFERROR(T45/T$47,"") -> 0.024974667 | Z45: 0.05 | AA45: vs 2025 | AB45: =AB15*AB21/10^6 -> 405.73802
E46: Siêu âm | F46: =5000000/(10^6) -> 5 | G46: =11100000/(10^6) -> 11.1 | H46: =10600000/(10^6) -> 10.6 | I46: =9050000/(10^6) -> 9.05 | J46: =7150000/(10^6) -> 7.15 | K46: =6550000/(10^6) -> 6.55 | L46: =13900000/(10^6) -> 13.9 | M46: =7450000/(10^6) -> 7.45 | N46: =12300000/(10^6) -> 12.3 | O46: =13500000/(10^6) -> 13.5 | P46: =7000000/(10^6) -> 7 | Q46: 11.3 | R46: =SUMIFS($F46:$Q46,$F$7:$Q$7,"A") -> 114.9 | S46: =SUMIFS($F46:$Q46,$F$7:$Q$7,"B") -> 0 | T46: =SUM(R46:S46) -> 114.9 | U46: =IFERROR(R46/R$47,"") -> 0.010303731 | V46: =IFERROR(S46/S$47,"") | W46: =IFERROR(T46/T$47,"") -> 0.010303731 | Z46: 0.05 | AA46: vs 2025 | AB46: =AB16*AB22/10^6 -> 163.22841
...

Sheet CaMau
G4: =10^6 -> 1000000
B6: BÁO CÁO KẾT QUẢ HOẠT ĐỘNG KINH DOANH CHI NHÁNH
B7: CÀ MAU | F7: A | G7: A | H7: A | I7: A | J7: A | K7: A | L7: A | M7: A | N7: A | O7: A | P7: A | Q7: A
B8: Năm tài chính 2025 | F8: Tháng | R8: ------------------Tổng-------------------- | U8: ------%Doanh thu------- | X8: ------------vs--------------
B9: VND triệu | F9: 1 | G9: 2 | H9: 3 | I9: 4 | J9: 5 | K9: 6 | L9: 7 | M9: 8 | N9: 9 | O9: 10 | P9: 11 | Q9: 12 | R9: Year to date | S9: Year to go | T9: LATEST ESTIMATE | U9: YTD | V9: YTG | W9: LE | X9: Last month | Y9: Last year | Z9: Assumption | AA9: Note | AB9: 2026F
B10: Doanh thu
D11: Chẩn đoán hình ảnh
E12: MRI | F12: =185580000/(10^6) -> 185.58 | G12: =339300000/(10^6) -> 339.3 | H12: =407700000/(10^6) -> 407.7 | I12: =500400000/(10^6) -> 500.4 | J12: =477000000/(10^6) -> 477 | K12: =592830000/(10^6) -> 592.83 | L12: =457650000/(10^6) -> 457.65 | M12: =463500000/(10^6) -> 463.5 | N12: =436530000/(10^6) -> 436.53 | O12: =506580000/(10^6) -> 506.58 | P12: =473700000/(10^6) -> 473.7 | Q12: 353.65 | R12: =SUMIFS($F12:$Q12,$F$7:$Q$7,"A") -> 5194.42 | S12: =SUMIFS($F12:$Q12,$F$7:$Q$7,"B") -> 0 | T12: =SUM(R12:S12) -> 5194.42 | U12: =IFERROR(R12/R$17,"") -> 0.95899581 | V12: =IFERROR(S12/S$17,"") | W12: =IFERROR(T12/T$17,"") -> 0.95899581 | Z12: 0.05 | AA12: vs 2025 | AB12: =AB94*T105/10^6 -> 6413.7849
E13: Mammo X-Quang | F13: =8000000/(10^6) -> 8 | G13: =8000000/(10^6) -> 8 | H13: =25500000/(10^6) -> 25.5 | I13: =15500000/(10^6) -> 15.5 | J13: =16800000/(10^6) -> 16.8 | K13: =39300000/(10^6) -> 39.3 | L13: =19400000/(10^6) -> 19.4 | M13: =24500000/(10^6) -> 24.5 | N13: =14000000/(10^6) -> 14 | O13: =11500000/(10^6) -> 11.5 | P13: =26200000/(10^6) -> 26.2 | Q13: 13.4 | R13: =SUMIFS($F13:$Q13,$F$7:$Q$7,"A") -> 222.1 | S13: =SUMIFS($F13:$Q13,$F$7:$Q$7,"B") -> 0 | T13: =SUM(R13:S13) -> 222.1 | U13: =IFERROR(R13/R$17,"") -> 0.041004187 | V13: =IFERROR(S13/S$17,"") | W13: =IFERROR(T13/T$17,"") -> 0.041004187 | Z13: 0.05 | AA13: vs 2025 | AB13: =AB95*T106/10^6 -> 376.08294
E14: CT | Q14: =P14 -> 0 | R14: =SUMIFS($F14:$Q14,$F$7:$Q$7,"A") -> 0 | S14: =SUMIFS($F14:$Q14,$F$7:$Q$7,"B") -> 0 | T14: =SUM(R14:S14) -> 0 | U14: =IFERROR(R14/R$17,"") -> 0 | V14: =IFERROR(S14/S$17,"") | W14: =IFERROR(T14/T$17,"") -> 0 | Z14: 0.05 | AA14: vs 2025 | AB14: =T14*(1+Z14) -> 0
E15: X-Quang | Q15: =P15 -> 0 | R15: =SUMIFS($F15:$Q15,$F$7:$Q$7,"A") -> 0 | S15: =SUMIFS($F15:$Q15,$F$7:$Q$7,"B") -> 0 | T15: =SUM(R15:S15) -> 0 | U15: =IFERROR(R15/R$17,"") -> 0 | V15: =IFERROR(S15/S$17,"") | W15: =IFERROR(T15/T$17,"") -> 0 | Z15: 0.05 | AA15: vs 2025 | AB15: =T15*(1+Z15) -> 0
E16: Siêu âm | Q16: =P16 -> 0 | R16: =SUMIFS($F16:$Q16,$F$7:$Q$7,"A") -> 0 | S16: =SUMIFS($F16:$Q16,$F$7:$Q$7,"B") -> 0 | T16: =SUM(R16:S16) -> 0 | U16: =IFERROR(R16/R$17,"") -> 0 | V16: =IFERROR(S16/S$17,"") | W16: =IFERROR(T16/T$17,"") -> 0 | Z16: 0.05 | AA16: vs 2025 | AB16: =T16*(1+Z16) -> 0
D17: Tổng- Chẩn đoán hình ảnh | F17: =SUM(F12:F16) -> 193.58 | G17: =SUM(G12:G16) -> 347.3 | H17: =SUM(H12:H16) -> 433.2 | I17: =SUM(I12:I16) -> 515.9 | J17: =SUM(J12:J16) -> 493.8 | K17: =SUM(K12:K16) -> 632.13 | L17: =SUM(L12:L16) -> 477.05 | M17: =SUM(M12:M16) -> 488 | ... Q17: =SUM(Q12:Q16) -> 367.05 | R17: =SUMIFS($F17:$Q17,$F$7:$Q$7,"A") -> 5416.52 | S17: =SUMIFS($F17:$Q17,$F$7:$Q$7,"B") -> 0 | T17: =SUM(R17:S17) -> 5416.52 | U17: =IFERROR(R17/R$17,"") -> 1 | V17: =IFERROR(S17/S$17,"") | W17: =IFERROR(T17/T$17,"") -> 1 | AB17: =SUM(AB12:AB16) -> 6789.8679
D18: Tổng- Khác | R18: =SUMIFS($F18:$Q18,$F$7:$Q$7,"A") -> 0 | S18: =SUMIFS($F18:$Q18,$F$7:$Q$7,"B") -> 0 | T18: =SUM(R18:S18) -> 0 | U18: =IFERROR(R18/R$17,"") -> 0 | V18: =IFERROR(S18/S$17,"") | W18: =IFERROR(T18/T$17,"") -> 0 | AB18: 0
B19: Tổng- Doanh thu | F19: =SUM(F17,F18) -> 193.58 | G19: =SUM(G17,G18) -> 347.3 | H19: =SUM(H17,H18) -> 433.2 | I19: =SUM(I17,I18) -> 515.9 | J19: =SUM(J17,J18) -> 493.8 | K19: =SUM(K17,K18) -> 632.13 | L19: =SUM(L17,L18) -> 477.05 | M19: =SUM(M17,M18) -> 488 | ... Q19: =SUM(Q17,Q18) -> 367.05 | R19: =SUMIFS($F19:$Q19,$F$7:$Q$7,"A") -> 5416.52 | S19: =SUMIFS($F19:$Q19,$F$7:$Q$7,"B") -> 0 | T19: =SUM(R19:S19) -> 5416.52 | U19: =IFERROR(R19/R$17,"") -> 1 | V19: =IFERROR(S19/S$17,"") | W19: =IFERROR(T19/T$17,"") -> 1 | AB19: =SUM(AB17,AB18) -> 6789.8679
B20: Giảm trừ doanh thu | F20: =SUBTOTAL(9,F21:F25) -> 0 | G20: =SUBTOTAL(9,G21:G25) -> 0 | H20: =SUBTOTAL(9,H21:H25) -> 0 | I20: =SUBTOTAL(9,I21:I25) -> 0 | J20: =SUBTOTAL(9,J21:J25) -> 0.45 | K20: =SUBTOTAL(9,K21:K25) -> 0.45 | L20: =SUBTOTAL(9,L21:L25) -> 0 | M20: =SUBTOTAL(9,M21:M25) -> 0 | ... Q20: =SUBTOTAL(9,Q21:Q25) -> 0 | R20: =SUMIFS($F20:$Q20,$F$7:$Q$7,"A") -> 0.9 | S20: =SUMIFS($F20:$Q20,$F$7:$Q$7,"B") -> 0 | T20: =SUM(R20:S20) -> 0.9 | U20: =IFERROR(R20/R$17,"") -> 0.00016615835 | V20: =IFERROR(S20/S$17,"") | W20: =IFERROR(T20/T$17,"") -> 0.00016615835 | AB20: 0
E21: MRI | J21: 0.45 | K21: 0.45 | Q21: 0
E22: Mammo X-Quang
E23: CT
E24: X-Quang
E25: Siêu âm
B26: Biến phí
C27: Vật tư tiêu hao | F27: 0.89703358 | G27: 1.5717934 | H27: 2.1354162 | I27: 2.35769 | J27: 2.3021216 | K27: 3.2547236 | L27: 2.2862449 | M27: 2.3735667 | N27: 2.0639711 | O27: 2.3497517 | P27: 2.4847036 | Q27: 1.7146837 | R27: =SUMIFS($F27:$Q27,$F$7:$Q$7,"A") -> 25.7917 | S27: =SUMIFS($F27:$Q27,$F$7:$Q$7,"B") -> 0 | T27: =SUM(R27:S27) -> 25.7917 | U27: =IFERROR(R27/R$17,"") -> 0.0047616735 | V27: =IFERROR(S27/S$17,"") | W27: =IFERROR(T27/T$17,"") -> 0.0047616735 | Z27: =W27 -> 0.0047616735 | AA27: % doanh thu | AB27: =Z27*$AB$17 -> 32.331134
C28: Chi phí đọc kết quả online | F28: =12345000/(10^6) -> 12.345 | G28: =21890000/(10^6) -> 21.89 | H28: =28130000/(10^6) -> 28.13 | I28: =32450000/(10^6) -> 32.45 | J28: =31425000/(10^6) -> 31.425 | K28: =42255000/(10^6) -> 42.255 | L28: =30920000/(10^6) -> 30.92 | M28: =32180000/(10^6) -> 32.18 | N28: =28825000/(10^6) -> 28.825 | O28: =33005000/(10^6) -> 33.005 | P28: =33385000/(10^6) -> 33.385 | Q28: 23.695 | R28: =SUMIFS($F28:$Q28,$F$7:$Q$7,"A") -> 350.505 | S28: =SUMIFS($F28:$Q28,$F$7:$Q$7,"B") -> 0 | T28: =SUM(R28:S28) -> 350.505 | U28: =IFERROR(R28/R$17,"") -> 0.064710368 | V28: =IFERROR(S28/S$17,"") | W28: =IFERROR(T28/T$17,"") -> 0.064710368 | Z28: =W28 -> 0.064710368 | AA28: % doanh thu | AB28: =Z28*$AB$17 -> 439.37484
C29: Tiền thuốc | Q29: =P29 -> 0 | R29: =SUMIFS($F29:$Q29,$F$7:$Q$7,"A") -> 0 | S29: =SUMIFS($F29:$Q29,$F$7:$Q$7,"B") -> 0 | T29: =SUM(R29:S29) -> 0 | U29: =IFERROR(R29/R$17,"") -> 0 | V29: =IFERROR(S29/S$17,"") | W29: =IFERROR(T29/T$17,"") -> 0 | Z29: =W29 -> 0 | AA29: % doanh thu | AB29: =Z29*$AB$17 -> 0
C30: Tư vấn chuyên môn | F30: =31300000/(10^6) -> 31.3 | G30: =55900000/(10^6) -> 55.9 | H30: =69900000/(10^6) -> 69.9 | I30: =82700000/(10^6) -> 82.7 | J30: =76000000/(10^6) -> 76 | K30: =75350000/(10^6) -> 75.35 | L30: =64940000/(10^6) -> 64.94 | M30: =69930000/(10^6) -> 69.93 | N30: =63410000/(10^6) -> 63.41 | O30: =76000000/(10^6) -> 76 | P30: =69370000/(10^6) -> 69.37 | Q30: 52.35 | R30: =SUMIFS($F30:$Q30,$F$7:$Q$7,"A") -> 787.15 | S30: =SUMIFS($F30:$Q30,$F$7:$Q$7,"B") -> 0 | T30: =SUM(R30:S30) -> 787.15 | U30: =IFERROR(R30/R$17,"") -> 0.14532393 | V30: =IFERROR(S30/S$17,"") | W30: =IFERROR(T30/T$17,"") -> 0.14532393 | Z30: =W30 -> 0.14532393 | AA30: % doanh thu | AB30: =Z30*$AB$17 -> 986.73032
C31: Thưởng hiệu quả kinh doanh nhân viên | Q31: =P31 -> 0 | R31: =SUMIFS($F31:$Q31,$F$7:$Q$7,"A") -> 0 | S31: =SUMIFS($F31:$Q31,$F$7:$Q$7,"B") -> 0 | T31: =SUM(R31:S31) -> 0 | U31: =IFERROR(R31/R$17,"") -> 0 | V31: =IFERROR(S31/S$17,"") | W31: =IFERROR(T31/T$17,"") -> 0 | Z31: =W31 -> 0 | AA31: % doanh thu | AB31: =Z31*$AB$17 -> 0
C32: Truyền thông marketing | Q32: =P32 -> 0 | R32: =SUMIFS($F32:$Q32,$F$7:$Q$7,"A") -> 0 | S32: =SUMIFS($F32:$Q32,$F$7:$Q$7,"B") -> 0 | T32: =SUM(R32:S32) -> 0 | U32: =IFERROR(R32/R$17,"") -> 0 | V32: =IFERROR(S32/S$17,"") | W32: =IFERROR(T32/T$17,"") -> 0 | Z32: 0.01 | AA32: % doanh thu | AB32: =Z32*$AB$17 -> 67.898679
B33: Tổng- Biến phí | F33: =SUM(F27:F32) -> 44.542034 | G33: =SUM(G27:G32) -> 79.361793 | H33: =SUM(H27:H32) -> 100.16542 | I33: =SUM(I27:I32) -> 117.50769 | J33: =SUM(J27:J32) -> 109.72712 | K33: =SUM(K27:K32) -> 120.85972 | L33: =SUM(L27:L32) -> 98.146245 | M33: =SUM(M27:M32) -> 104.48357 | ... Q33: =SUM(Q27:Q32) -> 77.759684 | R33: =SUMIFS($F33:$Q33,$F$7:$Q$7,"A") -> 1163.4467 | S33: =SUMIFS($F33:$Q33,$F$7:$Q$7,"B") -> 0 | T33: =SUM(R33:S33) -> 1163.4467 | U33: =IFERROR(R33/R$17,"") -> 0.21479598 | V33: =IFERROR(S33/S$17,"") | W33: =IFERROR(T33/T$17,"") -> 0.21479598 | AB33: =SUM(AB27:AB32) -> 1526.335
B34: Lãi trên biến phí | F34: =F19-F33-F20 -> 149.03797 | G34: =G19-G33-G20 -> 267.93821 | H34: =H19-H33-H20 -> 333.03458 | I34: =I19-I33-I20 -> 398.39231 | J34: =J19-J33-J20 -> 383.62288 | K34: =K19-K33-K20 -> 510.82028 | L34: =L19-L33-L20 -> 378.90376 | M34: =M19-M33-M20 -> 383.51643 | ... Q34: =Q19-Q33-Q20 -> 289.29032 | R34: =SUMIFS($F34:$Q34,$F$7:$Q$7,"A") -> 4252.1733 | S34: =SUMIFS($F34:$Q34,$F$7:$Q$7,"B") -> 0 | T34: =SUM(R34:S34) -> 4252.1733 | U34: =IFERROR(R34/R$17,"") -> 0.78503787 | V34: =IFERROR(S34/S$17,"") | W34: =IFERROR(T34/T$17,"") -> 0.78503787 | AB34: =AB19-AB33-AB20 -> 5263.5329
B35: Định phí | R35: =SUMIFS($F35:$Q35,$F$7:$Q$7,"A") -> 0 | S35: =SUMIFS($F35:$Q35,$F$7:$Q$7,"B") -> 0 | T35: =SUM(R35:S35) -> 0 | U35: =IFERROR(R35/R$17,"") -> 0 | V35: =IFERROR(S35/S$17,"") | W35: =IFERROR(T35/T$17,"") -> 0
C36: Chi phí nhân viên | F36: =74788325/(10^6) -> 74.788325 | G36: =60580772/(10^6) -> 60.580772 | H36: =59675998/(10^6) -> 59.675998 | I36: =56324863/(10^6) -> 56.324863 | J36: =57694576/(10^6) -> 57.694576 | K36: =58799179/(10^6) -> 58.799179 | L36: =63526899/(10^6) -> 63.526899 | M36: =62426611/(10^6) -> 62.426611 | N36: =63625989/(10^6) -> 63.625989 | O36: =67977071/(10^6) -> 67.977071 | P36: =68159326/(10^6) -> 68.159326 | Q36: 68.448783 | R36: =SUMIFS($F36:$Q36,$F$7:$Q$7,"A") -> 762.02839 | S36: =SUMIFS($F36:$Q36,$F$7:$Q$7,"B") -> 0 | T36: =SUM(R36:S36) -> 762.02839 | U36: =IFERROR(R36/R$17,"") -> 0.14068597 | V36: =IFERROR(S36/S$17,"") | W36: =IFERROR(T36/T$17,"") -> 0.14068597 | Z36: 0.02 | AA36: vs 2025 | AB36: =T36*(1+Z36) -> 777.26896
C37: Chi phí thuê địa điểm | F37: =20000000/(10^6) -> 20 | G37: =20000000/(10^6) -> 20 | H37: =20000000/(10^6) -> 20 | I37: =20000000/(10^6) -> 20 | J37: =20000000/(10^6) -> 20 | K37: =20000000/(10^6) -> 20 | L37: =20000000/(10^6) -> 20 | M37: =20000000/(10^6) -> 20 | ... Q37: =20000000/(10^6) -> 20 | R37: =SUMIFS($F37:$Q37,$F$7:$Q$7,"A") -> 240 | S37: =SUMIFS($F37:$Q37,$F$7:$Q$7,"B") -> 0 | T37: =SUM(R37:S37) -> 240 | U37: =IFERROR(R37/R$17,"") -> 0.044308892 | V37: =IFERROR(S37/S$17,"") | W37: =IFERROR(T37/T$17,"") -> 0.044308892 | Z37: 0.02 | AA37: vs 2025 | AB37: =T37*(1+Z37) -> 244.8
C38: Chi phí bảo dưỡng bảo trì máy | R38: =SUMIFS($F38:$Q38,$F$7:$Q$7,"A") -> 0 | S38: =SUMIFS($F38:$Q38,$F$7:$Q$7,"B") -> 0 | T38: =SUM(R38:S38) -> 0 | U38: =IFERROR(R38/R$17,"") -> 0 | V38: =IFERROR(S38/S$17,"") | W38: =IFERROR(T38/T$17,"") -> 0 | AA38: Đề xuất PKT | AB38: ='Site list'!Q5 -> 250.30125
C39: Chi phí vận hành thường xuyên | F39: 43.601338 | G39: 40.172091 | H39: 40.0567 | I39: 47.423887 | J39: 35.223744 | K39: 39.25273 | L39: 35.016929 | M39: 37.277475 | N39: 43.818602 | O39: 34.01631 | P39: 34.076323 | Q39: 40.820495 | R39: =SUMIFS($F39:$Q39,$F$7:$Q$7,"A") -> 470.75663 | S39: =SUMIFS($F39:$Q39,$F$7:$Q$7,"B") -> 0 | T39: =SUM(R39:S39) -> 470.75663 | U39: =IFERROR(R39/R$17,"") -> 0.086911269 | V39: =IFERROR(S39/S$17,"") | W39: =IFERROR(T39/T$17,"") -> 0.086911269 | AA39: không đổi | AB39: =T39 -> 470.75663
C40: Chi phí khác | F40: 50.7629 | G40: 11.6332 | H40: 0.7867 | I40: 67.058228 | J40: 8.3632 | K40: 1.713334 | L40: 4.7722 | M40: 29.473866 | N40: 2.327242 | O40: 1.266691 | P40: 0.6932 | Q40: 5.550515 | R40: =SUMIFS($F40:$Q40,$F$7:$Q$7,"A") -> 184.40128 | S40: =SUMIFS($F40:$Q40,$F$7:$Q$7,"B") -> 0 | T40: =SUM(R40:S40) -> 184.40128 | U40: =IFERROR(R40/R$17,"") -> 0.034044234 | V40: =IFERROR(S40/S$17,"") | W40: =IFERROR(T40/T$17,"") -> 0.034044234 | AA40: không đổi | AB40: =T40 -> 184.40128
B41: Tổng- Định phí | F41: =SUM(F36:F40) -> 189.15256 | G41: =SUM(G36:G40) -> 132.38606 | H41: =SUM(H36:H40) -> 120.5194 | I41: =SUM(I36:I40) -> 190.80698 | J41: =SUM(J36:J40) -> 121.28152 | K41: =SUM(K36:K40) -> 119.76524 | L41: =SUM(L36:L40) -> 123.31603 | M41: =SUM(M36:M40) -> 149.17795 | ... Q41: =SUM(Q36:Q40) -> 134.81979 | R41: =SUMIFS($F41:$Q41,$F$7:$Q$7,"A") -> 1657.1863 | S41: =SUMIFS($F41:$Q41,$F$7:$Q$7,"B") -> 0 | T41: =SUM(R41:S41) -> 1657.1863 | U41: =IFERROR(R41/R$17,"") -> 0.30595037 | V41: =IFERROR(S41/S$17,"") | W41: =IFERROR(T41/T$17,"") -> 0.30595037 | AB41: =SUM(AB36:AB40) -> 1927.5281
B42: EBITDA | F42: =F34-F41 -> -40.114597 | G42: =G34-G41 -> 135.55214 | H42: =H34-H41 -> 212.51519 | I42: =I34-I41 -> 207.58533 | J42: =J34-J41 -> 262.34136 | K42: =K34-K41 -> 391.05503 | L42: =L34-L41 -> 255.58773 | M42: =M34-M41 -> 234.33848 | ... Q42: =Q34-Q41 -> 154.47052 | R42: =SUMIFS($F42:$Q42,$F$7:$Q$7,"A") -> 2594.987 | S42: =SUMIFS($F42:$Q42,$F$7:$Q$7,"B") -> 0 | T42: =SUM(R42:S42) -> 2594.987 | U42: =IFERROR(R42/R$17,"") -> 0.4790875 | V42: =IFERROR(S42/S$17,"") | W42: =IFERROR(T42/T$17,"") -> 0.4790875 | AB42: =AB34-AB41 -> 3336.0048
B43: EBITDA về công ty mẹ | R43: =SUMIFS($F43:$Q43,$F$7:$Q$7,"A") -> 0 | S43: =SUMIFS($F43:$Q43,$F$7:$Q$7,"B") -> 0 | T43: =SUM(R43:S43) -> 0 | U43: =IFERROR(R43/R$17,"") -> 0 | V43: =IFERROR(S43/S$17,"") | W43: =IFERROR(T43/T$17,"") -> 0 | Z43: ='Site list'!H5 -> 0.55 | AA43: Tỷ lệ sở hữu | AB43: =AB42*Z43 -> 1834.8026
R44: =SUMIFS($F44:$Q44,$F$7:$Q$7,"A") -> 0 | S44: =SUMIFS($F44:$Q44,$F$7:$Q$7,"B") -> 0 | T44: =SUM(R44:S44) -> 0 | U44: =IFERROR(R44/R$17,"") -> 0 | V44: =IFERROR(S44/S$17,"") | W44: =IFERROR(T44/T$17,"") -> 0
...

Sheet ThanhHoa
G2: =10^6 -> 1000000
B6: BÁO CÁO KẾT QUẢ HOẠT ĐỘNG KINH DOANH CHI NHÁNH VÀ DỰ BÁO 2026
B7: THANH HÓA | F7: A | G7: A | H7: A | I7: A | J7: A | K7: A | L7: A | M7: A | N7: A | O7: A | P7: A | Q7: A
B8: Năm tài chính 2025 | F8: Tháng | R8: ------------------Tổng-------------------- | U8: ------%Doanh thu------- | X8: ------------vs--------------
